Workbook

Sheet 0分
A1: 周 | B1: 5^0 | C1: 地 | D1: Σ | E1: 0₦t | F1: ∀₦t | G1: فجر | I1: شروق | K1: صباح | M1: ظهر | O1: عصر | Q1: آصيل | S1: غروب | U1: غسق | W1: صدفة | Y1: -1₦ | Z1: 0₲ | AA1: i9 | AB1: m7 | AC1: 个 | AD1: 媒 | AE1: 思 | AF1: hcb | AG1: 家 | AH1: 社 | AI1: n156 | AL1: 1₲
A2: 1.1 | B2: 45662 | C2: sf21 | D2: =SUM(Y2:AH2) | E2: ='0₦'!AF5 | F2: ='0₦'!AG5 | K2: 1 | L2: 303 | M2: 1 | N2: 273 | O2: 1 | P2: 281 | Q2: 1 | R2: 211 | S2: 1 | T2: 183 | U2: 1 | V2: 386 | W2: 1 | X2: =D2-SUM(H2,J2,L2,N2,P2,R2,T2,V2) | Y2: =12*COUNT(G2,I2,K2,M2,O2,Q2,U2,W2,S2) | Z2: =9+40+100 | AA2: ='0₦'!BI5 + 30 | AB2: ='0₦'!BE5 + 30 + 50 + 30 + 30 + 16 + 30 + 20 + 10 + 30 + 20 + 10 | AC2: ='0₦'!BC5 + 5+10 + 10 + 30 + 20 + 20 + 20 + 20 + 20 + 20 + 20 + 20 + 15+20 + 20 + 40 | AD2: ='0₦'!BD5 | AE2: ='0₦'!AX5 | AF2: =hcbi!AA6+hcbi!Y6 | AG2: ='0₦'!AW5 + 5 + 60 + 120 + 60 + 15 + 60 + 40 | AH2: =0 | AI2: #VALUE! | AJ2: #VALUE! | AK2: 577 | AL2: 184
B3: =B2+1 | C3: sf21 | D3: =SUM(Y3:AH3) | E3: ='0₦'!AF6 | F3: ='0₦'!AG6 | I3: 1 | J3: 251 | K3: 1 | L3: 373 | M3: 1 | N3: 154 | O3: 1 | P3: 139 | Q3: 1 | R3: 145 | S3: 1 | T3: 153 | U3: 1 | V3: 225 | W3: 1 | X3: =D3-SUM(H3,J3,L3,N3,P3,R3,T3,V3) | Y3: =12*COUNT(G3,I3,K3,M3,O3,Q3,U3,W3,S3) | Z3: =9+40 + 80 + 50 | AA3: ='0₦'!BI6 + 30 + 40 + 51 + '1₦+'!AA4 + 60 + 10+'1₦+'!K4 + 45 + 10 + 30 + 30 | AB3: ='0₦'!BE6 + 30 | AC3: ='0₦'!BC6 + 40 + 20 + 10 + 5 + '0₦'!K4+'0₦'!M4+'0₦'!E61 + 10 + 160 | AD3: ='0₦'!BD6 | AE3: =19+20 | AF3: =hcbi!AA7+hcbi!Y7 | AG3: ='0₦'!AW6 + 15 | AH3: =0 | AK3: 699 | AL3: 137
B4: =B3+1 | C4: SEA | D4: =SUM(Y4:AH4) | E4: ='0₦'!AF7 | F4: ='0₦'!AG7 | G4: 1 | H4: 12 | I4: 1 | J4: 321 | K4: 1 | L4: 208 | M4: 1 | N4: 223 | O4: 1 | P4: 205 | Q4: 1 | R4: 200 | S4: 1 | T4: 200 | U4: 1 | V4: 80 | W4: 1 | X4: =D4-SUM(H4,J4,L4,N4,P4,R4,T4,V4) | Y4: =12*COUNT(G4,I4,K4,M4,O4,Q4,U4,W4,S4) | Z4: =9+50+30+50 | AA4: ='0₦'!BI7 + 10 + 15 + 30 + 15 + 7 + 10 + 150 - 20+45+30+30 +50 | AB4: ='0₦'!BE7 + 6 + 10 + 15 + 10 + 10 | AC4: ='0₦'!BC7 + 15 + 7 + 20 + 10 + 43 | AD4: ='0₦'!BD7 | AE4: ='0₦'!AX7+15+'1₦+'!W4+'1₦+'!U4 | AF4: =hcbi!AA8+hcbi!Y8 | AG4: ='0₦'!AW7 + 15 + 20 + 30 | AH4: 240 | AI4: #VALUE! | AJ4: #VALUE! | AK4: 770 | AL4: 103
B5: =B4+1 | C5: SEA | D5: =SUM(Y5:AH5) | E5: ='0₦'!AF8 | F5: ='0₦'!AG8 | I5: 1 | J5: 140 | K5: 1 | L5: 187 | M5: 1 | N5: 250 | O5: 1 | P5: 130 | Q5: 1 | R5: 318 | S5: 1 | T5: 134 | U5: 1 | V5: 120 | W5: 1 | X5: =D5-SUM(H5,J5,L5,N5,P5,R5,T5,V5) | Y5: =12*COUNT(G5,I5,K5,M5,O5,Q5,U5,W5,S5) | Z5: =9+40+60+40 | AA5: ='0₦'!BI8 + 340 + 40 + 30 + 30 + 60 + 200 - 20 | AB5: ='0₦'!BE8 + 30 + 20 | AC5: ='0₦'!BC8 + 0 | AD5: ='0₦'!BD8 | AE5: ='0₦'!AX8 | AF5: =hcbi!AA9+hcbi!Y9 | AG5: ='0₦'!AW8 | AH5: =90+20 + 30 | AK5: 867 | AL5: 136
B6: =B5+1 | C6: SEA | D6: =SUM(Y6:AH6) | E6: ='0₦'!AF9 | F6: ='0₦'!AG9 | G6: 1 | H6: 12 | I6: 1 | J6: 335 | K6: 1 | L6: 307 | M6: 1 | N6: 170 | O6: 1 | P6: 207 | Q6: 1 | R6: 200 | S6: 1 | T6: 205 | U6: 1 | V6: 100 | W6: 1 | X6: =D6-SUM(H6,J6,L6,N6,P6,R6,T6,V6) | Y6: =12*COUNT(G6,I6,K6,M6,O6,Q6,U6,W6,S6) | Z6: =9 + 30 | AA6: ='0₦'!BI9+100*1.5+120+10+64+3+20 + 20 + 10 + 10 + 20 + 30 + 45 + 30 | AB6: ='0₦'!BE9 | AC6: ='0₦'!BC9 + 200 | AD6: ='0₦'!BD9 | AE6: ='0₦'!AX9 | AF6: =hcbi!AA10+hcbi!Y10 | AG6: ='0₦'!AW9 | AH6: =90 + 67 | AI6: #VALUE! | AJ6: #VALUE! | AK6: 839 | AL6: 74
B7: =B6+1 | C7: sf21 | D7: =SUM(Y7:AH7) | E7: ='0₦'!AF10 | F7: ='0₦'!AG10 | G7: 1 | H7: 12 | I7: 1 | J7: 12 | K7: 1 | L7: 277 | M7: 1 | N7: 212 | O7: 1 | P7: 302 | Q7: 1 | R7: 309 | S7: 1 | T7: 304 | U7: 1 | V7: 100 | W7: 1 | X7: =D7-SUM(H7,J7,L7,N7,P7,R7,T7,V7) | Y7: =12*COUNT(G7,I7,K7,M7,O7,Q7,U7,W7,S7) | Z7: =9+50 + 50 + 40 + 20 | AA7: ='0₦'!BI10 + 300 + 30 + 60 + 14*8 + 15 + 100 + 10 + 30 | AB7: ='0₦'!BE10 + 10 + 10 | AC7: ='0₦'!BC10 + 20 + 20 + 20 + 15 + 26 | AD7: ='0₦'!BD10 | AE7: ='0₦'!AX10 + 30 | AF7: =hcbi!AA11+hcbi!Y11 + 25 | AG7: ='0₦'!AW10 | AH7: =24 + 60 + 20 + 20 | AK7: 890 | AL7: 69
B8: =B7+1 | C8: sf21 | D8: =SUM(Y8:AH8) | E8: ='0₦'!AF11 | F8: ='0₦'!AG11 | G8: 1 | H8: 12 | I8: 1 | J8: 205 | K8: 1 | L8: 315 | M8: 1 | N8: =450-53 | O8: 1 | P8: 209 | Q8: 1 | R8: 142 | S8: 1 | T8: 125 | U8: 1 | V8: 298 | W8: 1 | X8: =D8-SUM(H8,J8,L8,N8,P8,R8,T8,V8) | Y8: =12*COUNT(G8,I8,K8,M8,O8,Q8,U8,W8,S8) | Z8: =9+50 + 30 + 10 + 30 + 30 + 40 | AA8: ='0₦'!BI11 + 10 + 30 | AB8: ='0₦'!BE11 + 25 + 10 + 10 + 30 | AC8: ='0₦'!BC11 + 0 - 26 + 70 + 10 + 20 + 25 | AD8: ='0₦'!BD11 | AE8: ='0₦'!AX11 + 30 | AF8: =hcbi!AA12+hcbi!Y12 | AG8: ='0₦'!AW11 + 60 + 30 + 30 + 60 + 17 + 35 + 30 + 15 + 20 + 30 | AH8: =120+15 + 180 | AI8: #VALUE! | AJ8: #VALUE! | AK8: 723 | AL8: 74
A9: =A2+0.1 | B9: =B8+1 | C9: sf21 | D9: =SUM(Y9:AH9) | E9: ='0₦'!AF12 | F9: ='0₦'!AG12 | G9: 1 | H9: 12 | I9: 1 | J9: 270 | K9: 1 | L9: 180 | M9: 1 | N9: 277 | O9: 1 | P9: 326 | Q9: 1 | R9: 300 | S9: 1 | T9: 292 | U9: 1 | V9: 145 | W9: 1 | X9: =D9-SUM(H9,J9,L9,N9,P9,R9,T9,V9) | Y9: =12*COUNT(G9,I9,K9,M9,O9,Q9,U9,W9,S9) | Z9: =9+60 + 30 + 40 + 100 + 30 + 30 | AA9: ='0₦'!BI12 + 45 + 90 - 10 | AB9: ='0₦'!BE12 + 30 + 30 + 10 + 30 + 90 + 30 | AC9: ='0₦'!BC12 + 10+'1₦+'!C5+'1₦+'!D5 + '1₦+'!T104 + 40 + 26 | AD9: ='0₦'!BD12 | AE9: ='0₦'!AX12 | AF9: =hcbi!AA13+hcbi!Y13 | AG9: ='0₦'!AW12 | AH9: =15+120 + 180 | AK9: 697 | AL9: 23
B10: =B9+1 | C10: sf21 | D10: =SUM(Y10:AH10) | E10: ='0₦'!AF13 | F10: ='0₦'!AG13 | I10: 1 | J10: 194 | K10: 1 | L10: 130 | M10: 1 | N10: 115 | O10: 1 | P10: 78 | S10: 1 | T10: 165 | U10: 1 | V10: 125 | W10: 1 | X10: =D10-SUM(H10,J10,L10,N10,P10,R10,T10,V10) | Y10: =12*COUNT(G10,I10,K10,M10,O10,Q10,U10,W10,S10) | Z10: =9+30+50 | AA10: ='0₦'!BI13 + 25 + 30 + 10 + 30 + 60 - 10 - 20 | AB10: ='0₦'!BE13 + 30 | AC10: ='0₦'!BC13 + -26 + 20 + 15 | AD10: ='0₦'!BD13 | AE10: ='0₦'!AX13 | AF10: =hcbi!AA14+hcbi!Y14 | AG10: ='0₦'!AW13 + 10 | AH10: 26 | AI10: #VALUE! | AJ10: #VALUE! | AK10: 755 | AL10: 266
B11: =B10+1 | C11: sf21 | D11: =SUM(Y11:AH11) | E11: ='0₦'!AF14 | F11: ='0₦'!AG14 | K11: 1 | L11: 224 | M11: 1 | N11: 220 | O11: 1 | P11: 103 | Q11: 1 | R11: 153 | S11: 1 | T11: 163 | U11: 1 | V11: 176 | W11: 1 | X11: =D11-SUM(H11,J11,L11,N11,P11,R11,T11,V11) | Y11: =12*COUNT(G11,I11,K11,M11,O11,Q11,U11,W11,S11) | Z11: =IF(AND('0₦'!T14<>0,'0₦'!T14<>""),9,0) + 40 + 30 | AA11: ='0₦'!BI14 + 30+30 + 60 + 30 + 10 + 30 + 10 + 30 + 30 + 30 | AB11: ='0₦'!BE14 + 30 + 10 + 10 | AC11: ='0₦'!BC14 + '1₦+'!X5 | AD11: ='0₦'!BD14 | AE11: ='0₦'!AX14 | AF11: =hcbi!AA15+hcbi!Y15 | AG11: ='0₦'!AW14 + 23 + '1₦+'!P5 + SUM('1₦+'!N5:O5) | AH11: =0 | AK11: =760 | AL11: 507
B12: =B11+1 | C12: sf21 | D12: =SUM(Y12:AH12) | E12: ='0₦'!AF15 | F12: ='0₦'!AG15 | I12: 1 | J12: 168 | K12: 1 | L12: 229 | M12: 1 | N12: 266 | O12: 1 | P12: 229 | Q12: 1 | R12: 193 | S12: 1 | T12: 144 | U12: 1 | V12: 177 | W12: 1 | X12: =D12-SUM(H12,J12,L12,N12,P12,R12,T12,V12) | Y12: =12*COUNT(G12,I12,K12,M12,O12,Q12,U12,W12,S12) | Z12: =IF(AND('0₦'!T15<>0,'0₦'!T15<>""),9,0) + 15 + 20 + 30 + 15 + 100 | AA12: ='0₦'!BI15 + 30 + 40 + 30 + 20 + 30 + 5 + 10 + 10 + 25 + 30 + 30 + 10 + 60 | AB12: ='0₦'!BE15 + 35 + 100 + 20 + 10 + 21 | AC12: ='0₦'!BC15 + 30 | AD12: ='0₦'!BD15 | AE12: ='0₦'!AX15+'1₦+'!U5 | AF12: =hcbi!AA16+hcbi!Y16 + 25 | AG12: ='0₦'!AW15 | AH12: =0+15+'1₦+'!R5+10+'1₦+'!R4 + 20 + 7 | AI12: #VALUE! | AJ12: #VALUE! | AK12: 777 | AL12: 569
B13: =B12+1 | C13: SEA | D13: =SUM(Y13:AH13) | E13: ='0₦'!AF16 | F13: ='0₦'!AG16 | G13: 1 | H13: 12 | I13: 1 | J13: 12 | K13: 1 | L13: 298 | M13: 1 | N13: 145 | O13: 1 | P13: 271 | Q13: 1 | R13: 127 | S13: 1 | T13: 118 | U13: 1 | V13: 245 | X13: =D13-SUM(H13,J13,L13,N13,P13,R13,T13,V13) | Y13: =12*COUNT(G13,I13,K13,M13,O13,Q13,U13,W13,S13) | Z13: =IF(AND('0₦'!T16<>0,'0₦'!T16<>""),9,0) + 20 | AA13: ='0₦'!BI16 + 10+35 + 40 + 30 + 90 + 60 + 30 + 45 + 30 + 30 + 30 - 20 + 20 | AB13: ='0₦'!BE16 + 100 + 15 + 10 | AC13: ='0₦'!BC16 + 12 | AD13: ='0₦'!BD16 | AE13: ='0₦'!AX16 + 14 | AF13: =hcbi!AA17+hcbi!Y17 + 20 | AG13: ='0₦'!AW16 | AH13: =150 | AK13: 690 | AL13: 89
B14: =B13+1 | C14: SEA | D14: =SUM(Y14:AH14) | E14: ='0₦'!AF17 | F14: ='0₦'!AG17 | G14: 1 | H14: 12 | I14: 1 | J14: 75 | K14: 1 | L14: 499 | M14: 1 | N14: 148 | O14: 1 | P14: 168 | Q14: 1 | R14: 171 | S14: 1 | T14: 187 | U14: 1 | V14: 227 | W14: 1 | X14: =D14-SUM(H14,J14,L14,N14,P14,R14,T14,V14) | Y14: =12*COUNT(G14,I14,K14,M14,O14,Q14,U14,W14,S14) | Z14: =IF(AND('0₦'!T17<>0,'0₦'!T17<>""),9,0) + 60 + 30 + 80 + 40 + 30 | AA14: ='0₦'!BI17 + 10 + 300 - 15 + 10 + 20 + 40 + 60 + 30 | AB14: ='0₦'!BE17+30 + 10 + 250 + 15 + 10 + 45 | AC14: ='0₦'!BC17 + 5 + 15 + 20 + 10 | AD14: ='0₦'!BD17+'1₦+'!S5 | AE14: ='0₦'!AX17+'1₦+'!W5 + 18 | AF14: =hcbi!AA18+hcbi!Y18 + 15 | AG14: ='0₦'!AW17 | AH14: =7 + 30 + 10 + 35 + 10 | AI14: #VALUE! | AJ14: #VALUE! | AK14: 583 | AL14: 57
B15: =B14+1 | C15: sf21 | D15: =SUM(Y15:AH15) | E15: ='0₦'!AF18 | F15: ='0₦'!AG18 | G15: 1 | H15: 14 | I15: 1 | J15: 232 | K15: 1 | L15: 229 | M15: 1 | N15: 200 | O15: 1 | P15: 200 | Q15: 1 | R15: 200 | S15: 1 | T15: 200 | U15: 1 | V15: 205 | W15: 1 | X15: =D15-SUM(H15,J15,L15,N15,P15,R15,T15,V15) | Y15: =12*COUNT(G15,I15,K15,M15,O15,Q15,U15,W15,S15) | Z15: =IF(AND('0₦'!T18<>0,'0₦'!T18<>""),9,0) + 70 + 150+ 30 + 40 | AA15: ='0₦'!BI18+10 | AB15: ='0₦'!BE18+25 | AC15: ='0₦'!BC18 + 60 + 3 | AD15: ='0₦'!BD18 | AE15: ='0₦'!AX18 | AF15: =hcbi!AA19+hcbi!Y19 | AG15: ='0₦'!AW18 + 30 + 30 + 120 + 30 | AH15: =120 | AK15: 379 | AL15: 164
A16: =A9+0.1 | B16: =B15+1 | C16: sf21 | D16: =SUM(Y16:AH16) | E16: ='0₦'!AF19 | F16: ='0₦'!AG19 | G16: 1 | H16: 12 | I16: 1 | J16: 249 | K16: 1 | L16: 187 | M16: 1 | N16: 125 | O16: 1 | P16: 213 | Q16: 1 | R16: 215 | S16: 1 | T16: 200 | U16: 1 | V16: 150 | W16: 1 | X16: =D16-SUM(H16,J16,L16,N16,P16,R16,T16,V16) | Y16: =12*COUNT(G16,I16,K16,M16,O16,Q16,U16,W16,S16) | Z16: =IF(AND('0₦'!T19<>0,'0₦'!T19<>""),9,0) + 50 + 90 + 60 | AA16: ='0₦'!BI19 + 0 | AB16: ='0₦'!BE19 + 30 + 10 + 15 + 30 + 30 + 30 + 15 +15 + 20 + 30 + 20 + 36 + 10 + 100 | AC16: ='0₦'!BC19 + 60 + 20 | AD16: ='0₦'!BD19 | AE16: ='0₦'!AX19 | AF16: =hcbi!AA20+hcbi!Y20 | AG16: ='0₦'!AW19 + 60 + 90 + 60 | AH16: =0 | AI16: #VALUE! | AJ16: #VALUE! | AK16: 463 | AL16: 196
B17: =B16+1 | C17: sf21 | D17: =SUM(Y17:AH17) | E17: ='0₦'!AF20 | F17: ='0₦'!AG20 | K17: 1 | L17: 200 | M17: 1 | N17: 200 | O17: 1 | P17: 200 | Q17: 1 | R17: 200 | S17: 1 | T17: 195 | U17: 1 | V17: =D17-SUM(H17,J17,L17,N17,P17,R17,T17) | Y17: =12*COUNT(G17,I17,K17,M17,O17,Q17,U17,W17,S17) | Z17: =9+60 + 30 + 45 | AA17: ='0₦'!BI20 + -5 - 20 | AB17: ='0₦'!BE20 - 15 | AC17: ='0₦'!BC20 + 60 - 10 - 20 | AD17: ='0₦'!BD20 | AE17: ='0₦'!AX20 | AF17: =hcbi!AA21+hcbi!Y21 | AG17: ='0₦'!AW20 + 30 + 120 + 120 + 120 + 180 | AH17: =20+20+20+20 + 10 | AK17: 774 | AL17: 904
B18: =B17+1 | C18: sf21 | D18: =SUM(Y18:AH18) | E18: ='0₦'!AF21 | F18: ='0₦'!AG21 | I18: 1 | J18: 132 | K18: 1 | L18: 302 | M18: 1 | N18: 132 | O18: 1 | P18: 242 | Q18: 1 | R18: 305 | S18: 1 | T18: 208 | U18: 1 | V18: =D18-SUM(H18,J18,L18,N18,P18,R18,T18) | W18: 1 | X18: =D18-SUM(H18,J18,L18,N18,P18,R18,T18,V18) | Y18: =12*COUNT(G18,I18,K18,M18,O18,Q18,U18,W18,S18) | Z18: =IF(AND('0₦'!T21<>0,'0₦'!T21<>""),9,0) + 60 + 40 + 40 + 40 | AA18: ='0₦'!BI21 + 35 + 10 + 5 + 20 + 30 + 30 + 30 + 50 + 30 + 30 + 10 | AB18: ='0₦'!BE21 + 15 + 20 + 100 + 30 + 10 + 7 | AC18: ='0₦'!BC21 + 10 + 20 + 5 - 26 | AD18: ='0₦'!BD21 | AE18: ='0₦'!AX21 + 21 | AF18: =hcbi!AA22+hcbi!Y22 + 20 | AG18: ='0₦'!AW21+10 + 15 + 30 + 20 | AH18: =20+20 | AI18: #VALUE! | AJ18: #VALUE! | AK18: 845 | AL18: 343
B19: =B18+1 | C19: SEA | D19: =SUM(Y19:AH19) | E19: ='0₦'!AF22 | F19: ='0₦'!AG22 | G19: 1 | H19: 12 | I19: 1 | J19: 233 | K19: 1 | L19: 135 | M19: 1 | N19: 234 | O19: 1 | P19: 120 | Q19: 1 | R19: 151 | S19: 1 | T19: 239 | U19: 1 | V19: 200 | W19: 1 | X19: =D19-SUM(H19,J19,L19,N19,P19,R19,T19,V19) | Y19: =12*COUNT(G19,I19,K19,M19,O19,Q19,U19,W19,S19) | Z19: =IF(AND('0₦'!T22<>0,'0₦'!T22<>""),9,0) + 80 + 60 + 40 + 40 | AA19: ='0₦'!BI22 + 60 + 20 + 20 + 40 + 45 + 40 + 30*6 + 30 - 20 | AB19: ='0₦'!BE22 + 50 + 15 + 100 | AC19: ='0₦'!BC22 + 26 + 15 | AD19: ='0₦'!BD22 | AE19: ='0₦'!AX22 + 15 | AF19: =hcbi!AA23+hcbi!Y23 | AG19: ='0₦'!AW22 | AH19: =10 + 20 + 120 + 21 | AK19: 757 | AL19: 533
B20: =B19+1 | C20: SEA | D20: =SUM(Y20:AH20) | E20: ='0₦'!AF23 | F20: ='0₦'!AG23 | G20: 1 | H20: 12 | I20: 1 | J20: 343 | K20: 1 | L20: 303 | M20: 1 | N20: 212 | O20: 1 | P20: 114 | Q20: 1 | R20: 193 | S20: 1 | T20: 231 | U20: 1 | V20: 221 | W20: 1 | X20: =D20-SUM(H20,J20,L20,N20,P20,R20,T20,V20) | Y20: =12*COUNT(G20,I20,K20,M20,O20,Q20,U20,W20,S20) | Z20: =IF(AND('0₦'!T23<>0,'0₦'!T23<>""),9,0) + 50 + 30 + 40 + 46 | AA20: ='0₦'!BI23 + 60 + 30 + 30 + 40 + 10 + 30 + 30 + 20 + 10 + 30 + 30 + 25 - 20 | AB20: ='0₦'!BE23 + 10 + 45 + 15 + 100 + 30+'1₦+'!G6 | AC20: ='0₦'!BC23 + 20+'1₦+'!L6+'1₦+'!D6+'1₦+'!C6 | AD20: ='0₦'!BD23 + 10 | AE20: ='0₦'!AX23 + '1₦+'!Z7 + 30 + 30 + 30 + 25 + 30 + 11 | AF20: =hcbi!AA24+hcbi!Y24 + 15 | AG20: ='0₦'!AW23 | AH20: =25 + 10 | AI20: #VALUE! | AK20: 764 | AL20: 258
B21: =B20+1 | C21: SEA | D21: =SUM(Y21:AH21) | E21: ='0₦'!AF24 | F21: ='0₦'!AG24 | G21: 1 | H21: 12 | I21: 1 | J21: 90 | K21: 1 | L21: 379 | M21: 1 | N21: 212 | O21: 1 | P21: 200 | Q21: 1 | R21: 107 | S21: 1 | T21: 283 | U21: 1 | V21: 115 | W21: 1 | X21: =D21-SUM(H21,J21,L21,N21,P21,R21,T21,V21) | Y21: =12*COUNT(G21,I21,K21,M21,O21,Q21,U21,W21,S21) | Z21: =IF(AND('0₦'!T24<>0,'0₦'!T24<>""),9,0) + 50 + 20 + 20 | AA21: ='0₦'!BI24 + 40 + 300 + 45 + 30 + 30 + 30 | AB21: ='0₦'!BE24 + 30 + 15 +30 | AC21: ='0₦'!BC24 + '1₦+'!Y6 + 20 | AD21: ='0₦'!BD24 | AE21: ='0₦'!AX24 | AF21: =hcbi!AA25+hcbi!Y25 | AG21: ='0₦'!AW24 + 30 | AH21: =30 + 100 | AK21: 750 | AL21: 402
B22: =B21+1 | C22: sf21 | D22: =SUM(Y22:AH22) | E22: ='0₦'!AF25 | F22: ='0₦'!AG25 | G22: 1 | H22: 12 | I22: 1 | J22: =D22-H22 | L22: =D22-SUM(H22,J22) | N22: =D22-SUM(H22,J22,L22,) | P22: =D22-SUM(H22,J22,L22,N22) | R22: =D22-SUM(H22,J22,L22,N22,P22) | T22: =D22-SUM(H22,J22,L22,N22,P22,R22) | V22: =D22-SUM(H22,J22,L22,N22,P22,R22,T22) | X22: =D22-SUM(H22,J22,L22,N22,P22,R22,T22,V22) | Y22: =12*COUNT(G22,I22,K22,M22,O22,Q22,U22,W22,S22) | Z22: =IF(AND('0₦'!T25<>0,'0₦'!T25<>""),9,0) + 0 | AA22: ='0₦'!BI25 + 0 | AB22: ='0₦'!BE25 | AC22: ='0₦'!BC25 + 0 | AD22: ='0₦'!BD25 | AE22: ='0₦'!AX25 | AF22: =hcbi!AA26+hcbi!Y26 | AG22: ='0₦'!AW25 | AH22: =0 | AK22: 768 | AL22: 116
A23: =A16+0.1 | B23: =B22+1 | C23: sf21 | D23: =SUM(Y23:AH23) | E23: ='0₦'!AF26 | F23: ='0₦'!AG26 | H23: =D23 | J23: =D23-H23 | L23: =D23-SUM(H23,J23) | N23: =D23-SUM(H23,J23,L23,) | P23: =D23-SUM(H23,J23,L23,N23) | R23: =D23-SUM(H23,J23,L23,N23,P23) | T23: =D23-SUM(H23,J23,L23,N23,P23,R23) | V23: =D23-SUM(H23,J23,L23,N23,P23,R23,T23) | X23: =D23-SUM(H23,J23,L23,N23,P23,R23,T23,V23) | Y23: =12*COUNT(G23,I23,K23,M23,O23,Q23,U23,W23,S23) | Z23: =IF(AND('0₦'!T26<>0,'0₦'!T26<>""),9,0) + 0 | AA23: ='0₦'!BI26 + 0 | AB23: ='0₦'!BE26 | AC23: ='0₦'!BC26 + 0 | AD23: ='0₦'!BD26 | AE23: ='0₦'!AX26 | AF23: =hcbi!AA27+hcbi!Y27 | AG23: ='0₦'!AW26 | AH23: =0 | AK23: 523 | AL23: 14
B24: =B23+1 | C24: sf21 | D24: =SUM(Y24:AH24) | E24: ='0₦'!AF27 | F24: ='0₦'!AG27 | H24: =D24 | J24: =D24-H24 | L24: =D24-SUM(H24,J24) | N24: =D24-SUM(H24,J24,L24,) | P24: =D24-SUM(H24,J24,L24,N24) | R24: =D24-SUM(H24,J24,L24,N24,P24) | T24: =D24-SUM(H24,J24,L24,N24,P24,R24) | V24: =D24-SUM(H24,J24,L24,N24,P24,R24,T24) | X24: =D24-SUM(H24,J24,L24,N24,P24,R24,T24,V24) | Y24: =12*COUNT(G24,I24,K24,M24,O24,Q24,U24,W24,S24) | Z24: =IF(AND('0₦'!T27<>0,'0₦'!T27<>""),9,0) + 0 | AA24: ='0₦'!BI27 + 0 | AB24: ='0₦'!BE27 | AC24: ='0₦'!BC27 + 0 | AD24: ='0₦'!BD27 | AE24: ='0₦'!AX27 | AF24: =hcbi!AA28+hcbi!Y28 | AG24: ='0₦'!AW27 | AH24: =0 | AK24: 523 | AL24: 100
B25: =B24+1 | C25: sf21 | D25: =SUM(Y25:AH25) | E25: ='0₦'!AF28 | F25: ='0₦'!AG28 | H25: =D25 | J25: =D25-H25 | L25: =D25-SUM(H25,J25) | N25: =D25-SUM(H25,J25,L25,) | P25: =D25-SUM(H25,J25,L25,N25) | R25: =D25-SUM(H25,J25,L25,N25,P25) | T25: =D25-SUM(H25,J25,L25,N25,P25,R25) | V25: =D25-SUM(H25,J25,L25,N25,P25,R25,T25) | X25: =D25-SUM(H25,J25,L25,N25,P25,R25,T25,V25) | Y25: =12*COUNT(G25,I25,K25,M25,O25,Q25,U25,W25,S25) | Z25: =IF(AND('0₦'!T28<>0,'0₦'!T28<>""),9,0) + 0 | AA25: ='0₦'!BI28 + 0 | AB25: ='0₦'!BE28 | AC25: ='0₦'!BC28 + 0 | AD25: ='0₦'!BD28 | AE25: ='0₦'!AX28 | AF25: =hcbi!AA29+hcbi!Y29 | AG25: ='0₦'!AW28 | AH25: =0 | AK25: 656 | AL25: 1000
B26: =B25+1 | C26: sf21 | D26: =SUM(Y26:AH26) | E26: ='0₦'!AF29 | F26: ='0₦'!AG29 | H26: =D26 | J26: =D26-H26 | L26: =D26-SUM(H26,J26) | N26: =D26-SUM(H26,J26,L26,) | P26: =D26-SUM(H26,J26,L26,N26) | R26: =D26-SUM(H26,J26,L26,N26,P26) | T26: =D26-SUM(H26,J26,L26,N26,P26,R26) | V26: =D26-SUM(H26,J26,L26,N26,P26,R26,T26) | X26: =D26-SUM(H26,J26,L26,N26,P26,R26,T26,V26) | Y26: =12*COUNT(G26,I26,K26,M26,O26,Q26,U26,W26,S26) | Z26: =IF(AND('0₦'!T29<>0,'0₦'!T29<>""),9,0) + 0 | AA26: ='0₦'!BI29 + 0 | AB26: ='0₦'!BE29 | AC26: ='0₦'!BC29 + 0 | AD26: ='0₦'!BD29 | AE26: ='0₦'!AX29 | AF26: =hcbi!AA30+hcbi!Y30 | AG26: ='0₦'!AW29 | AH26: =0 | AK26: 623 | AL26: 45
B27: =B26+1 | C27: sf21 | D27: =SUM(Y27:AH27) | E27: ='0₦'!AF30 | F27: ='0₦'!AG30 | H27: =D27 | J27: =D27-H27 | L27: =D27-SUM(H27,J27) | N27: =D27-SUM(H27,J27,L27,) | P27: =D27-SUM(H27,J27,L27,N27) | R27: =D27-SUM(H27,J27,L27,N27,P27) | T27: =D27-SUM(H27,J27,L27,N27,P27,R27) | V27: =D27-SUM(H27,J27,L27,N27,P27,R27,T27) | X27: =D27-SUM(H27,J27,L27,N27,P27,R27,T27,V27) | Y27: =12*COUNT(G27,I27,K27,M27,O27,Q27,U27,W27,S27) | Z27: =IF(AND('0₦'!T30<>0,'0₦'!T30<>""),9,0) + 0 | AA27: ='0₦'!BI30 + 0 | AB27: ='0₦'!BE30 | AC27: ='0₦'!BC30 + 0 | AD27: ='0₦'!BD30 | AE27: ='0₦'!AX30 | AF27: =hcbi!AA31+hcbi!Y31 | AG27: ='0₦'!AW30 | AH27: =0 | AK27: 658 | AL27: 129
B28: =B27+1 | C28: sf21 | D28: =SUM(Y28:AH28) | E28: ='0₦'!AF31 | F28: ='0₦'!AG31 | H28: =D28 | J28: =D28-H28 | L28: =D28-SUM(H28,J28) | N28: =D28-SUM(H28,J28,L28,) | P28: =D28-SUM(H28,J28,L28,N28) | R28: =D28-SUM(H28,J28,L28,N28,P28) | T28: =D28-SUM(H28,J28,L28,N28,P28,R28) | V28: =D28-SUM(H28,J28,L28,N28,P28,R28,T28) | X28: =D28-SUM(H28,J28,L28,N28,P28,R28,T28,V28) | Y28: =12*COUNT(G28,I28,K28,M28,O28,Q28,U28,W28,S28) | Z28: =IF(AND('0₦'!T31<>0,'0₦'!T31<>""),9,0) + 0 | AA28: ='0₦'!BI31 + 0 | AB28: ='0₦'!BE31 | AC28: ='0₦'!BC31 + 0 | AD28: ='0₦'!BD31 | AE28: ='0₦'!AX31 | AF28: =hcbi!AA32+hcbi!Y32 | AG28: ='0₦'!AW31 | AH28: =0 | AK28: 620 | AL28: 100
B29: =B28+1 | C29: sf21 | D29: =SUM(Y29:AH29) | E29: ='0₦'!AF32 | F29: ='0₦'!AG32 | H29: =D29 | J29: =D29-H29 | L29: =D29-SUM(H29,J29) | N29: =D29-SUM(H29,J29,L29,) | P29: =D29-SUM(H29,J29,L29,N29) | R29: =D29-SUM(H29,J29,L29,N29,P29) | T29: =D29-SUM(H29,J29,L29,N29,P29,R29) | V29: =D29-SUM(H29,J29,L29,N29,P29,R29,T29) | X29: =D29-SUM(H29,J29,L29,N29,P29,R29,T29,V29) | Y29: =12*COUNT(G29,I29,K29,M29,O29,Q29,U29,W29,S29) | Z29: =IF(AND('0₦'!T32<>0,'0₦'!T32<>""),9,0) + 0 | AA29: ='0₦'!BI32 + 0 | AB29: ='0₦'!BE32 | AC29: ='0₦'!BC32 + 0 | AD29: ='0₦'!BD32 | AE29: ='0₦'!AX32 | AF29: =hcbi!AA33+hcbi!Y33 | AG29: ='0₦'!AW32 | AH29: =0 | AK29: 652 | AL29: 10
A30: =A2+1 | B30: =B29+1 | C30: sf21 | D30: =SUM(Y30:AH30) | E30: ='0₦'!AF33 | F30: ='0₦'!AG33 | H30: =D30 | J30: =D30-H30 | L30: =D30-SUM(H30,J30) | N30: =D30-SUM(H30,J30,L30,) | P30: =D30-SUM(H30,J30,L30,N30) | R30: =D30-SUM(H30,J30,L30,N30,P30) | T30: =D30-SUM(H30,J30,L30,N30,P30,R30) | V30: =D30-SUM(H30,J30,L30,N30,P30,R30,T30) | X30: =D30-SUM(H30,J30,L30,N30,P30,R30,T30,V30) | Y30: =12*COUNT(G30,I30,K30,M30,O30,Q30,U30,W30,S30) | Z30: =IF(AND('0₦'!T33<>0,'0₦'!T33<>""),9,0) + 0 | AA30: ='0₦'!BI33 + 0 | AB30: ='0₦'!BE33 | AC30: ='0₦'!BC33 + 0 | AD30: ='0₦'!BD33 | AE30: ='0₦'!AX33 | AF30: =hcbi!AA34+hcbi!Y34 | AG30: ='0₦'!AW33 | AH30: =0 | AK30: 798 | AL30: 125
B31: =B30+1 | C31: sf21 | D31: =SUM(Y31:AH31) | E31: ='0₦'!AF34 | F31: ='0₦'!AG34 | H31: =D31 | J31: =D31-H31 | L31: =D31-SUM(H31,J31) | N31: =D31-SUM(H31,J31,L31,) | P31: =D31-SUM(H31,J31,L31,N31) | R31: =D31-SUM(H31,J31,L31,N31,P31) | T31: =D31-SUM(H31,J31,L31,N31,P31,R31) | V31: =D31-SUM(H31,J31,L31,N31,P31,R31,T31) | X31: =D31-SUM(H31,J31,L31,N31,P31,R31,T31,V31) | Y31: =12*COUNT(G31,I31,K31,M31,O31,Q31,U31,W31,S31) | Z31: =IF(AND('0₦'!T34<>0,'0₦'!T34<>""),9,0) + 0 | AA31: ='0₦'!BI34 + 0 | AB31: ='0₦'!BE34 | AC31: ='0₦'!BC34 + 0 | AD31: ='0₦'!BD34 | AE31: ='0₦'!AX34 | AF31: =hcbi!AA35+hcbi!Y35 | AG31: ='0₦'!AW34 | AH31: =0 | AK31: 702 | AL31: 329
B32: =B31+1 | C32: sf21 | D32: =SUM(Y32:AH32) | E32: ='0₦'!AF35 | F32: ='0₦'!AG35 | H32: =D32 | J32: =D32-H32 | L32: =D32-SUM(H32,J32) | N32: =D32-SUM(H32,J32,L32,) | P32: =D32-SUM(H32,J32,L32,N32) | R32: =D32-SUM(H32,J32,L32,N32,P32) | T32: =D32-SUM(H32,J32,L32,N32,P32,R32) | V32: =D32-SUM(H32,J32,L32,N32,P32,R32,T32) | X32: =D32-SUM(H32,J32,L32,N32,P32,R32,T32,V32) | Y32: =12*COUNT(G32,I32,K32,M32,O32,Q32,U32,W32,S32) | Z32: =IF(AND('0₦'!T35<>0,'0₦'!T35<>""),9,0) + 0 | AA32: ='0₦'!BI35 + 0 | AB32: ='0₦'!BE35 | AC32: ='0₦'!BC35 + 0 | AD32: ='0₦'!BD35 | AE32: ='0₦'!AX35 | AF32: =hcbi!AA36+hcbi!Y36 | AG32: ='0₦'!AW35 | AH32: =0 | AK32: 727 | AL32: 523
B33: =B32+1 | C33: sf21 | D33: =SUM(Y33:AH33) | E33: ='0₦'!AF36 | F33: ='0₦'!AG36 | H33: =D33 | J33: =D33-H33 | L33: =D33-SUM(H33,J33) | N33: =D33-SUM(H33,J33,L33,) | P33: =D33-SUM(H33,J33,L33,N33) | R33: =D33-SUM(H33,J33,L33,N33,P33) | T33: =D33-SUM(H33,J33,L33,N33,P33,R33) | V33: =D33-SUM(H33,J33,L33,N33,P33,R33,T33) | X33: =D33-SUM(H33,J33,L33,N33,P33,R33,T33,V33) | Y33: =12*COUNT(G33,I33,K33,M33,O33,Q33,U33,W33,S33) | Z33: =IF(AND('0₦'!T36<>0,'0₦'!T36<>""),9,0) + 0 | AA33: ='0₦'!BI36 + 0 | AB33: ='0₦'!BE36 | AC33: ='0₦'!BC36 + 0 | AD33: ='0₦'!BD36 | AE33: ='0₦'!AX36 | AF33: =hcbi!AA37+hcbi!Y37 | AG33: ='0₦'!AW36 | AH33: =0 | AK33: 864 | AL33: 328
B34: =B33+1 | C34: sf21 | D34: =SUM(Y34:AH34) | E34: ='0₦'!AF37 | F34: ='0₦'!AG37 | H34: =D34 | J34: =D34-H34 | L34: =D34-SUM(H34,J34) | N34: =D34-SUM(H34,J34,L34,) | P34: =D34-SUM(H34,J34,L34,N34) | R34: =D34-SUM(H34,J34,L34,N34,P34) | T34: =D34-SUM(H34,J34,L34,N34,P34,R34) | V34: =D34-SUM(H34,J34,L34,N34,P34,R34,T34) | X34: =D34-SUM(H34,J34,L34,N34,P34,R34,T34,V34) | Y34: =12*COUNT(G34,I34,K34,M34,O34,Q34,U34,W34,S34) | Z34: =IF(AND('0₦'!T37<>0,'0₦'!T37<>""),9,0) + 0 | AA34: ='0₦'!BI37 + 0 | AB34: ='0₦'!BE37 | AC34: ='0₦'!BC37 + 0 | AD34: ='0₦'!BD37 | AE34: ='0₦'!AX37 | AF34: =hcbi!AA38+hcbi!Y38 | AG34: ='0₦'!AW37 | AH34: =0 | AK34: 757 | AL34: 574
B35: =B34+1 | C35: sf21 | D35: =SUM(Y35:AH35) | E35: ='0₦'!AF38 | F35: ='0₦'!AG38 | H35: =D35 | J35: =D35-H35 | L35: =D35-SUM(H35,J35) | N35: =D35-SUM(H35,J35,L35,) | P35: =D35-SUM(H35,J35,L35,N35) | R35: =D35-SUM(H35,J35,L35,N35,P35) | T35: =D35-SUM(H35,J35,L35,N35,P35,R35) | V35: =D35-SUM(H35,J35,L35,N35,P35,R35,T35) | X35: =D35-SUM(H35,J35,L35,N35,P35,R35,T35,V35) | Y35: =12*COUNT(G35,I35,K35,M35,O35,Q35,U35,W35,S35) | Z35: =IF(AND('0₦'!T38<>0,'0₦'!T38<>""),9,0) + 0 | AA35: ='0₦'!BI38 + 0 | AB35: ='0₦'!BE38 | AC35: ='0₦'!BC38 + 0 | AD35: ='0₦'!BD38 | AE35: ='0₦'!AX38 | AF35: =hcbi!AA39+hcbi!Y39 | AG35: ='0₦'!AW38 | AH35: =0 | AK35: 930 | AL35: 517
B36: =B35+1 | C36: sf21 | D36: =SUM(Y36:AH36) | E36: ='0₦'!AF39 | F36: ='0₦'!AG39 | H36: =D36 | J36: =D36-H36 | L36: =D36-SUM(H36,J36) | N36: =D36-SUM(H36,J36,L36,) | P36: =D36-SUM(H36,J36,L36,N36) | R36: =D36-SUM(H36,J36,L36,N36,P36) | T36: =D36-SUM(H36,J36,L36,N36,P36,R36) | V36: =D36-SUM(H36,J36,L36,N36,P36,R36,T36) | X36: =D36-SUM(H36,J36,L36,N36,P36,R36,T36,V36) | Y36: =12*COUNT(G36,I36,K36,M36,O36,Q36,U36,W36,S36) | Z36: =IF(AND('0₦'!T39<>0,'0₦'!T39<>""),9,0) + 0 | AA36: ='0₦'!BI39 + 0 | AB36: ='0₦'!BE39 | AC36: ='0₦'!BC39 + 0 | AD36: ='0₦'!BD39 | AE36: ='0₦'!AX39 | AF36: =hcbi!AA40+hcbi!Y40 | AG36: ='0₦'!AW39 | AH36: =0 | AK36: 923 | AL36: 117
A37: =A30+0.1 | B37: =B36+1 | C37: sf21 | D37: =SUM(Y37:AH37) | E37: ='0₦'!AF40 | F37: ='0₦'!AG40 | H37: =D37 | J37: =D37-H37 | L37: =D37-SUM(H37,J37) | N37: =D37-SUM(H37,J37,L37,) | P37: =D37-SUM(H37,J37,L37,N37) | R37: =D37-SUM(H37,J37,L37,N37,P37) | T37: =D37-SUM(H37,J37,L37,N37,P37,R37) | V37: =D37-SUM(H37,J37,L37,N37,P37,R37,T37) | X37: =D37-SUM(H37,J37,L37,N37,P37,R37,T37,V37) | Y37: =12*COUNT(G37,I37,K37,M37,O37,Q37,U37,W37,S37) | Z37: =IF(AND('0₦'!T40<>0,'0₦'!T40<>""),9,0) + 0 | AA37: ='0₦'!BI40 + 0 | AB37: ='0₦'!BE40 | AC37: ='0₦'!BC40 + 0 | AD37: ='0₦'!BD40 | AE37: ='0₦'!AX40 | AF37: =hcbi!AA41+hcbi!Y41 | AG37: ='0₦'!AW40 | AH37: =0 | AK37: 757 | AL37: 88
B38: =B37+1 | C38: sf21 | D38: =SUM(Y38:AH38) | E38: ='0₦'!AF41 | F38: ='0₦'!AG41 | H38: =D38 | J38: =D38-H38 | L38: =D38-SUM(H38,J38) | N38: =D38-SUM(H38,J38,L38,) | P38: =D38-SUM(H38,J38,L38,N38) | R38: =D38-SUM(H38,J38,L38,N38,P38) | T38: =D38-SUM(H38,J38,L38,N38,P38,R38) | V38: =D38-SUM(H38,J38,L38,N38,P38,R38,T38) | X38: =D38-SUM(H38,J38,L38,N38,P38,R38,T38,V38) | Y38: =12*COUNT(G38,I38,K38,M38,O38,Q38,U38,W38,S38) | Z38: =IF(AND('0₦'!T41<>0,'0₦'!T41<>""),9,0) + 0 | AA38: ='0₦'!BI41 + 0 | AB38: ='0₦'!BE41 | AC38: ='0₦'!BC41 + 0 | AD38: ='0₦'!BD41 | AE38: ='0₦'!AX41 | AF38: =hcbi!AA42+hcbi!Y42 | AG38: ='0₦'!AW41 | AH38: =0 | AK38: 917 | AL38: 515
B39: =B38+1 | C39: sf21 | D39: =SUM(Y39:AH39) | E39: ='0₦'!AF42 | F39: ='0₦'!AG42 | H39: =D39 | J39: =D39-H39 | L39: =D39-SUM(H39,J39) | N39: =D39-SUM(H39,J39,L39,) | P39: =D39-SUM(H39,J39,L39,N39) | R39: =D39-SUM(H39,J39,L39,N39,P39) | T39: =D39-SUM(H39,J39,L39,N39,P39,R39) | V39: =D39-SUM(H39,J39,L39,N39,P39,R39,T39) | X39: =D39-SUM(H39,J39,L39,N39,P39,R39,T39,V39) | Y39: =12*COUNT(G39,I39,K39,M39,O39,Q39,U39,W39,S39) | Z39: =IF(AND('0₦'!T42<>0,'0₦'!T42<>""),9,0) + 0 | AA39: ='0₦'!BI42 + 0 | AB39: ='0₦'!BE42 | AC39: ='0₦'!BC42 + 0 | AD39: ='0₦'!BD42 | AE39: ='0₦'!AX42 | AF39: =hcbi!AA43+hcbi!Y43 | AG39: ='0₦'!AW42 | AH39: =0 | AK39: 895 | AL39: 195
B40: =B39+1 | C40: sf21 | D40: =SUM(Y40:AH40) | E40: ='0₦'!AF43 | F40: ='0₦'!AG43 | H40: =D40 | J40: =D40-H40 | L40: =D40-SUM(H40,J40) | N40: =D40-SUM(H40,J40,L40,) | P40: =D40-SUM(H40,J40,L40,N40) | R40: =D40-SUM(H40,J40,L40,N40,P40) | T40: =D40-SUM(H40,J40,L40,N40,P40,R40) | V40: =D40-SUM(H40,J40,L40,N40,P40,R40,T40) | X40: =D40-SUM(H40,J40,L40,N40,P40,R40,T40,V40) | Y40: =12*COUNT(G40,I40,K40,M40,O40,Q40,U40,W40,S40) | Z40: =IF(AND('0₦'!T43<>0,'0₦'!T43<>""),9,0) + 0 | AA40: ='0₦'!BI43 + 0 | AB40: ='0₦'!BE43 | AC40: ='0₦'!BC43 + 0 | AD40: ='0₦'!BD43 | AE40: ='0₦'!AX43 | AF40: =hcbi!AA44+hcbi!Y44 | AG40: ='0₦'!AW43 | AH40: =0 | AK40: 762 | AL40: 413
...

Sheet 0₦
C1: 2026 | D1: 睡觉 | E1: cpap | F1: 起 | G1: i444 | H1: i47 | I1: 充 | J1: tmrw | K1: 2hci | L1: d hci | M1: @jm | N1: 新闻 | O1: 词汇 | P1: hcmc | Q1: 0t | R1: ₦156 | S1: 0l | T1: 0₲ | U1: stats | V1: notes | W1: @microsoft, @github | X1: 代 | Y1: tms | Z1: slack | AA1: slack | AB1: @m5 | AC1: dash | AD1: 早餐 | AE1: hiit | AF1: ⎣₦ | AG1: ⎣∀clr | AH1: # | AI1: 问学 | AJ1: qft | AK1: lx:qt | AL1: NVC + e | AM1: ص | AN1: o314 | AO1: 冥想 | AP1: 其他人 | AR1: 1+ | AS1: -1 | AT1: -2/-4 | AU1: -3 | AW1: ∑xk87 | AX1: ∑hcmt | AY1: ∑hcmc | AZ1: ∑hcb | BA1: 蠢之后 | BD1: hcmc | BE1: m5x2
C2: ⊖分 | D2: 30 | E2: 10 | F2: 6 | G2: 5 | H2: 5 | I2: 3 | J2: 5 | K2: 7 | L2: 26 | M2: 5 | N2: 2 | O2: 7 | P2: 10 | Q2: 10 | R2: 4 | S2: 20 | T2: 8 | U2: 10 | V2: 8 | W2: 20 | X2: 30 | Y2: 7 | Z2: 5 | AA2: 3 | AB2: 15 | AC2: 15 | AD2: 5 | AE2: 7 | AF2: =SUM(V2:AB2,S2:T2,M2,) | AI2: 60 | AJ2: 30 | AK2: 30 | AL2: 1 | AM2: 60 | AN2: 15 | AO2: 10 | AP2: 5 | AR2: 0 | AS2: 10 | AT2: 60 | AU2: 15 | AW2: =SUM(AI2:AL2) | AX2: =SUM(AM2:AP2) | AY2: =SUM(AU2+AT2*0.5)-AR2-#REF!*0.5+#REF!*0.5
C3: p(t) | D3: 500 | E3: 2 | H3: 5 | I3: 3 | J3: 3 | K3: 10 | L3: 25 | M3: 7 | Q3: 12 | R3: 4 | S3: 12 | T3: 6 | U3: 8 | V3: 5 | X3: 40 | AA3: 30 | AB3: 5 | AC3: 3 | AI3: 60 | AM3: 20 | AN3: 15 | AO3: 10 | AP3: 5 | AR3: 54
C4: Ideal time | D4: 480 | E4: 2 | F4: 5 | H4: 3 | I4: 1 | J4: 1 | K4: 8 | L4: 11 | M4: 6 | N4: 7 | O4: 7 | Q4: 5 | R4: 3 | S4: 8 | T4: 5 | U4: 6 | V4: 4 | X4: 30 | AA4: 10 | AB4: 3 | AC4: 2 | AD4: 12 | AE4: 35 | AH4: 3 | AI4: 45 | AJ4: 45 | AK4: 30 | AL4: 1 | AM4: 5 | AN4: =SUM(AN5:AN101)-COUNT(AN5:AN101)*15 | AO4: =SUM(AO5:AO101)-COUNT(AO5:AO101)*15 | AP4: =SUM(AP5:AP101)-COUNT(AP5:AP101)*5
A5: 1.1 | B5: S | C5: 46026 | D5: 540 | E5: 2 | F5: 13 | H5: 1 | I5: 1 | J5: 1 | K5: 5 | L5: 13 | M5: 1 | N5: 7 | O5: 5 | P5: 30 | Q5: 4 | R5: 1 | S5: 23 | T5: 3 | U5: 3 | V5: 4 | W5: 2 | Y5: 3 | Z5: 1 | AA5: 1 | AB5: 10 | AC5: 1 | AD5: 3 | AE5: 1 | AF5: 915 | AG5: 1406 | AH5: 2 | AI5: =51+10 | AJ5: =123+61 | AK5: 30 | AL5: 1 | AM5: 85 | AN5: 0 | AO5: 0 | AP5: 0 | AR5: -1 | AS5: =P5 | AT5: 10 | AU5: 7 | AW5: =SUM(AH5:AI5,AJ5/2,AK5:AL5) | AX5: =AM5*0.5+SUM(AN5:AP5) | AY5: =SUM(-AR5+AS5*0.01+AT5*0.5+AU5) | AZ5: ='0分'!AF2 | BA5: =SUM(AY5,AX5,AW5) | BC5: {=SUMPRODUCT(--(NOT(ISBLANK('0₦'!D5:M5))), '0₦'!D$2:M$2) + SUMPRODUCT(--(NOT(ISBLANK('0₦'!Q5:T5))), '0₦'!Q$2:T$2)} | BD5: {=SUMPRODUCT(--(NOT(ISBLANK('0₦'!N5:P5))),'0₦'!N$2:P$2)+'0₦'!AY5} | BE5: {=SUMPRODUCT(--(NOT(ISBLANK('0₦'!AA5:AC5))),'0₦'!AA$2:AC$2) + BF5} | BG5: {=SUMPRODUCT(--(NOT(ISBLANK('0₦'!U5:Z5))), '0₦'!U$2:Z$2)} | BI5: =SUM(BG5:BH5)
B6: M | C6: =C5+1 | D6: 484 | E6: 1 | F6: 3 | H6: 1 | I6: 1 | J6: 1 | K6: 7 | L6: 17 | M6: 3 | N6: 10 | P6: 65 | Q6: 1 | R6: 1 | S6: 6 | T6: 3 | U6: 2 | V6: 1 | W6: 1 | Y6: 1 | Z6: 1 | AA6: 1 | AB6: 1 | AC6: 1 | AD6: 3 | AE6: 1 | AF6: 753 | AG6: 1527 | AH6: 1 | AI6: =5+25+23+15 + 50 + 45 + 10 | AJ6: =22+60 | AK6: =15+36 | AL6: 1 | AM6: 90 | AN6: 9 | AO6: 0 | AP6: 0 | AR6: -1 | AS6: =P6 | AT6: 10 | AU6: 10 | AW6: =SUM(AH6:AI6,AJ6/2,AK6:AL6) | AX6: =AM6*0.5+SUM(AN6:AP6) | AY6: =SUM(-AR6+AS6*0.01+AT6*0.5+AU6) | AZ6: ='0分'!AF3 | BA6: =SUM(AY6,AX6,AW6) | BC6: {=SUMPRODUCT(--(NOT(ISBLANK('0₦'!D6:M6))), '0₦'!D$2:M$2) + SUMPRODUCT(--(NOT(ISBLANK('0₦'!Q6:T6))), '0₦'!Q$2:T$2)} | BD6: {=SUMPRODUCT(--(NOT(ISBLANK('0₦'!N6:P6))),'0₦'!N$2:P$2)+'0₦'!AY6} | BE6: {=SUMPRODUCT(--(NOT(ISBLANK('0₦'!AA6:AC6))),'0₦'!AA$2:AC$2) + BF6} | BG6: {=SUMPRODUCT(--(NOT(ISBLANK('0₦'!U6:Z6))), '0₦'!U$2:Z$2)} | BI6: =SUM(BG6:BH6)
B7: T | C7: =C6+1 | D7: 510 | E7: 2 | F7: 2 | G7: 240 | H7: 1 | I7: 1 | J7: 1 | K7: 5 | L7: 17 | M7: 7 | N7: 11 | P7: 30 | Q7: 4 | R7: 1 | S7: 8 | T7: 3 | U7: 2 | V7: 9 | W7: 20 | X7: 3 | Y7: 7 | Z7: 1 | AA7: 1 | AB7: 8 | AC7: 1 | AD7: 10 | AE7: 1 | AF7: 640 | AG7: 2145 | AH7: 0 | AI7: 0 | AJ7: 5 | AK7: 34 | AL7: 1 | AM7: 91 | AN7: 44 | AO7: 31 | AP7: 0 | AR7: -1 | AS7: =P7 | AT7: 10 | AU7: =11+12+44 | AW7: =SUM(AH7:AI7,AJ7/2,AK7:AL7) | AX7: =AM7*0.5+SUM(AN7:AP7) | AY7: =SUM(-AR7+AS7*0.01+AT7*0.5+AU7) | AZ7: ='0分'!AF4 | BA7: =SUM(AY7,AX7,AW7) | BC7: {=SUMPRODUCT(--(NOT(ISBLANK('0₦'!D7:M7))), '0₦'!D$2:M$2) + SUMPRODUCT(--(NOT(ISBLANK('0₦'!Q7:T7))), '0₦'!Q$2:T$2)} | BD7: {=SUMPRODUCT(--(NOT(ISBLANK('0₦'!N7:P7))),'0₦'!N$2:P$2)+'0₦'!AY7} | BE7: {=SUMPRODUCT(--(NOT(ISBLANK('0₦'!AA7:AC7))),'0₦'!AA$2:AC$2) + BF7} | BG7: {=SUMPRODUCT(--(NOT(ISBLANK('0₦'!U7:Z7))), '0₦'!U$2:Z$2)} | BI7: =SUM(BG7:BH7)
B8: W | C8: =C7+1 | D8: 523 | E8: 0 | F8: 3 | G8: 12 | H8: 1 | I8: 1 | J8: 1 | K8: 4 | L8: 30 | M8: 3 | N8: 12 | P8: 30 | Q8: 3 | R8: 4 | S8: 5 | T8: 3 | U8: 3 | V8: 4 | W8: 15 | Y8: 10 | Z8: 3 | AA8: 4 | AB8: 15 | AC8: 1 | AD8: 5 | AE8: 1 | AF8: 2102 | AH8: 0 | AI8: 0 | AJ8: 5 | AK8: 30 | AL8: 1 | AM8: 60 | AN8: 0 | AO8: 18 | AP8: 0 | AR8: 20 | AS8: =P8 | AT8: 10 | AU8: 12 | AW8: =SUM(AH8:AI8,AJ8/2,AK8:AL8) | AX8: =AM8*0.5+SUM(AN8:AP8) | AY8: =SUM(-AR8+AS8*0.01+AT8*0.5+AU8) | AZ8: ='0分'!AF5 | BA8: =SUM(AY8,AX8,AW8) | BC8: {=SUMPRODUCT(--(NOT(ISBLANK('0₦'!D8:M8))), '0₦'!D$2:M$2) + SUMPRODUCT(--(NOT(ISBLANK('0₦'!Q8:T8))), '0₦'!Q$2:T$2)} | BD8: {=SUMPRODUCT(--(NOT(ISBLANK('0₦'!N8:P8))),'0₦'!N$2:P$2)+'0₦'!AY8} | BE8: {=SUMPRODUCT(--(NOT(ISBLANK('0₦'!AA8:AC8))),'0₦'!AA$2:AC$2) + BF8} | BG8: {=SUMPRODUCT(--(NOT(ISBLANK('0₦'!U8:Z8))), '0₦'!U$2:Z$2)} | BI8: =SUM(BG8:BH8)
B9: Th | C9: =C8+1 | D9: 490 | E9: 0 | F9: 5 | G9: 15 | H9: 2 | I9: 1 | J9: 1 | K9: 3 | L9: 15 | M9: 2 | N9: 10 | P9: 30 | Q9: 2 | R9: 1 | S9: 6 | T9: 3 | U9: 2 | V9: 26 | W9: 15 | Y9: 15 | Z9: 2 | AA9: 1 | AB9: 5 | AC9: 1 | AD9: 22 | AE9: 1 | AF9: 1341 | AG9: 1344 | AH9: 1 | AI9: 0 | AJ9: 0 | AK9: 35 | AL9: 1 | AM9: 47 | AN9: 0 | AO9: 15 | AP9: 0 | AR9: -1 | AS9: 90 | AT9: 20 | AU9: 10 | AW9: =SUM(AH9:AI9,AJ9/2,AK9:AL9) | AX9: =AM9*0.5+SUM(AN9:AP9) | AY9: =SUM(-AR9+AS9*0.01+AT9*0.5+AU9) | AZ9: ='0分'!AF6 | BA9: =SUM(AY9,AX9,AW9) | BC9: {=SUMPRODUCT(--(NOT(ISBLANK('0₦'!D9:M9))), '0₦'!D$2:M$2) + SUMPRODUCT(--(NOT(ISBLANK('0₦'!Q9:T9))), '0₦'!Q$2:T$2)} | BD9: {=SUMPRODUCT(--(NOT(ISBLANK('0₦'!N9:P9))),'0₦'!N$2:P$2)+'0₦'!AY9} | BE9: {=SUMPRODUCT(--(NOT(ISBLANK('0₦'!AA9:AC9))),'0₦'!AA$2:AC$2) + BF9} | BG9: {=SUMPRODUCT(--(NOT(ISBLANK('0₦'!U9:Z9))), '0₦'!U$2:Z$2)} | BI9: =SUM(BG9:BH9)
B10: F | C10: =C9+1 | D10: 510 | E10: 0 | F10: 23 | G10: 15 | H10: 1 | I10: 1 | J10: 1 | K10: 4 | L10: 15 | M10: 3 | N10: 12 | P10: 30 | Q10: 4 | R10: 1 | S10: 4 | T10: 4 | U10: 2 | V10: 6 | W10: 20 | Y10: 10 | Z10: 1 | AA10: 3 | AB10: 15 | AC10: 3 | AD10: 25 | AE10: 1 | AF10: 901 | AG10: 2216 | AH10: 0 | AI10: =70+30+15+10+5+5 | AJ10: 45 | AK10: 35 | AL10: 1 | AM10: 67 | AN10: 15 | AO10: 16 | AP10: =18+22 | AR10: 2 | AS10: 30 | AT10: 35 | AU10: 12 | AW10: =SUM(AH10:AI10,AJ10/2,AK10:AL10) | AX10: =AM10*0.5+SUM(AN10:AP10) | AY10: =SUM(-AR10+AS10*0.01+AT10*0.5+AU10) | AZ10: ='0分'!AF7 | BA10: =SUM(AY10,AX10,AW10) | BC10: {=SUMPRODUCT(--(NOT(ISBLANK('0₦'!D10:M10))), '0₦'!D$2:M$2) + SUMPRODUCT(--(NOT(ISBLANK('0₦'!Q10:T10))), '0₦'!Q$2:T$2)} | BD10: {=SUMPRODUCT(--(NOT(ISBLANK('0₦'!N10:P10))),'0₦'!N$2:P$2)+'0₦'!AY10} | BE10: {=SUMPRODUCT(--(NOT(ISBLANK('0₦'!AA10:AC10))),'0₦'!AA$2:AC$2) + BF10} | BG10: {=SUMPRODUCT(--(NOT(ISBLANK('0₦'!U10:Z10))), '0₦'!U$2:Z$2)} | BI10: =SUM(BG10:BH10)
B11: S | C11: =C10+1 | D11: 422 | E11: 0 | F11: 15 | G11: 15 | H11: 1 | I11: 1 | J11: 1 | K11: 3 | L11: 12 | M11: 5 | N11: 13 | P11: 20 | Q11: 7 | R11: 1 | S11: 9 | T11: 5 | U11: 3 | V11: 2 | W11: 2 | Y11: 10 | Z11: 1 | AA11: 1 | AB11: 9 | AC11: 1 | AD11: 5 | AE11: 7 | AF11: 757 | AG11: 1537 | AH11: 0 | AI11: =23+10 + 18 + 5 + 17 + 35 + 10 + 61 | AJ11: 200 | AK11: 54 | AL11: 1 | AM11: 81 | AN11: 0 | AO11: 0 | AP11: 21 | AR11: -1 | AS11: 30 | AT11: 5 | AU11: 13 | AW11: =SUM(AH11:AI11,AJ11/2,AK11:AL11) | AX11: =AM11*0.5+SUM(AN11:AP11) | AY11: =SUM(-AR11+AS11*0.01+AT11*0.5+AU11) | AZ11: ='0分'!AF8 | BA11: =SUM(AY11,AX11,AW11) | BC11: {=SUMPRODUCT(--(NOT(ISBLANK('0₦'!D11:M11))), '0₦'!D$2:M$2) + SUMPRODUCT(--(NOT(ISBLANK('0₦'!Q11:T11))), '0₦'!Q$2:T$2)} | BD11: {=SUMPRODUCT(--(NOT(ISBLANK('0₦'!N11:P11))),'0₦'!N$2:P$2)+'0₦'!AY11} | BE11: {=SUMPRODUCT(--(NOT(ISBLANK('0₦'!AA11:AC11))),'0₦'!AA$2:AC$2) + BF11} | BG11: {=SUMPRODUCT(--(NOT(ISBLANK('0₦'!U11:Z11))), '0₦'!U$2:Z$2)} | BI11: =SUM(BG11:BH11)
A12: =A5+0.1 | B12: S | C12: =C11+1 | D12: 505 | E12: 0 | F12: 3 | H12: 1 | I12: 1 | J12: 1 | K12: 3 | L12: 15 | M12: 3 | N12: 11 | P12: 30 | Q12: 3 | R12: 2 | S12: 3 | T12: 4 | U12: 10 | V12: 5 | W12: 3 | Y12: 1 | Z12: 1 | AA12: 1 | AB12: 1 | AC12: 1 | AD12: 10 | AE12: 20 | AF12: 759 | AG12: 1315 | AH12: 0 | AI12: =70+33+24+10 | AJ12: 135 | AK12: 18 | AL12: 1 | AM12: 102 | AN12: 0 | AO12: 0 | AP12: =19+16 | AR12: -1 | AS12: 30 | AT12: 20 | AU12: =N12+O12 | AW12: =SUM(AH12:AI12,AJ12/2,AK12:AL12) | AX12: =AM12*0.5+SUM(AN12:AP12) | AY12: =SUM(-AR12+AS12*0.01+AT12*0.5+AU12) | AZ12: ='0分'!AF9 | BA12: =SUM(AY12,AX12,AW12) | BC12: {=SUMPRODUCT(--(NOT(ISBLANK('0₦'!D12:M12))), '0₦'!D$2:M$2) + SUMPRODUCT(--(NOT(ISBLANK('0₦'!Q12:T12))), '0₦'!Q$2:T$2)} | BD12: {=SUMPRODUCT(--(NOT(ISBLANK('0₦'!N12:P12))),'0₦'!N$2:P$2)+'0₦'!AY12} | BE12: {=SUMPRODUCT(--(NOT(ISBLANK('0₦'!AA12:AC12))),'0₦'!AA$2:AC$2) + BF12} | BG12: {=SUMPRODUCT(--(NOT(ISBLANK('0₦'!U12:Z12))), '0₦'!U$2:Z$2)} | BI12: =SUM(BG12:BH12)
B13: M | C13: =C12+1 | D13: 510 | E13: 0 | F13: 2 | G13: 12 | H13: 1 | I13: 1 | J13: 1 | K13: 3 | L13: 15 | M13: 3 | N13: 8 | P13: 30 | Q13: 6 | R13: 1 | S13: 12 | T13: 5 | U13: 4 | V13: 2 | W13: 10 | Y13: 15 | Z13: 1 | AA13: 3 | AB13: 2 | AC13: 1 | AD13: 15 | AE13: 43 | AF13: 811 | AG13: 1900 | AH13: 0 | AI13: =63+10+30+10 | AJ13: 0 | AK13: 24 | AL13: 1 | AM13: 88 | AN13: 0 | AO13: 0 | AP13: 0 | AR13: 20 | AS13: 150 | AT13: 30 | AU13: 16 | AW13: =SUM(AH13:AI13,AJ13/2,AK13:AL13) | AX13: =AM13*0.5+SUM(AN13:AP13) | AY13: =SUM(-AR13+AS13*0.01+AT13*0.5+AU13) | AZ13: ='0分'!AF10 | BA13: =SUM(AY13,AX13,AW13) | BC13: {=SUMPRODUCT(--(NOT(ISBLANK('0₦'!D13:M13))), '0₦'!D$2:M$2) + SUMPRODUCT(--(NOT(ISBLANK('0₦'!Q13:T13))), '0₦'!Q$2:T$2)} | BD13: {=SUMPRODUCT(--(NOT(ISBLANK('0₦'!N13:P13))),'0₦'!N$2:P$2)+'0₦'!AY13} | BE13: {=SUMPRODUCT(--(NOT(ISBLANK('0₦'!AA13:AC13))),'0₦'!AA$2:AC$2) + BF13} | BG13: {=SUMPRODUCT(--(NOT(ISBLANK('0₦'!U13:Z13))), '0₦'!U$2:Z$2)} | BI13: =SUM(BG13:BH13)
B14: T | C14: =C13+1 | D14: 570 | E14: 0 | F14: 2 | H14: 1 | I14: 1 | J14: 1 | K14: 2 | L14: 15 | M14: 2 | N14: 20 | P14: 60 | Q14: 4 | R14: 1 | S14: 12 | T14: 3 | U14: 6 | V14: 2 | W14: 5 | Y14: 15 | Z14: 3 | AA14: 3 | AB14: 17 | AC14: 1 | AD14: 15 | AE14: 1 | AF14: 1223 | AG14: 1952 | AH14: 0 | AI14: =45+5 + 20 + 5 + 60 + 5 | AJ14: 45 | AK14: =15+60 | AL14: 1 | AM14: 60 | AN14: 0 | AO14: 0 | AP14: 0 | AR14: -1 | AS14: 30 | AT14: 5 | AU14: =N14+O14 | AW14: =SUM(AH14:AI14,AJ14/2,AK14:AL14) | AX14: =AM14*0.5+SUM(AN14:AP14) | AY14: =SUM(-AR14+AS14*0.01+AT14*0.5+AU14) | AZ14: ='0分'!AF11 | BA14: =SUM(AY14,AX14,AW14) | BC14: {=SUMPRODUCT(--(NOT(ISBLANK('0₦'!D14:M14))), '0₦'!D$2:M$2) + SUMPRODUCT(--(NOT(ISBLANK('0₦'!Q14:T14))), '0₦'!Q$2:T$2)} | BD14: {=SUMPRODUCT(--(NOT(ISBLANK('0₦'!N14:P14))),'0₦'!N$2:P$2)+'0₦'!AY14} | BE14: {=SUMPRODUCT(--(NOT(ISBLANK('0₦'!AA14:AC14))),'0₦'!AA$2:AC$2) + BF14} | BG14: {=SUMPRODUCT(--(NOT(ISBLANK('0₦'!U14:Z14))), '0₦'!U$2:Z$2)} | BI14: =SUM(BG14:BH14)
B15: W | C15: =C14+1 | D15: 491 | E15: 2 | F15: 2 | H15: 1 | I15: 1 | J15: 1 | K15: 3 | L15: 15 | M15: 3 | N15: 11 | P15: 30 | Q15: 7 | R15: 2 | S15: 3 | T15: 1 | U15: 5 | V15: 6 | W15: 6 | Y15: 15 | Z15: 1 | AA15: 1 | AB15: 3 | AC15: 4 | AD15: 13 | AE15: 1 | AF15: 805 | AG15: 1348 | AH15: 0 | AI15: 54 | AJ15: 0 | AK15: =25+30 | AL15: 1 | AM15: 63 | AN15: 59 | AO15: =13+8 | AP15: =12 | AR15: -1 | AS15: 30 | AT15: 15 | AU15: 26 | AW15: =SUM(AH15:AI15,AJ15/2,AK15:AL15) | AX15: =AM15*0.5+SUM(AN15:AP15) | AY15: =SUM(-AR15+AS15*0.01+AT15*0.5+AU15) | AZ15: ='0分'!AF12 | BA15: =SUM(AY15,AX15,AW15) | BC15: {=SUMPRODUCT(--(NOT(ISBLANK('0₦'!D15:M15))), '0₦'!D$2:M$2) + SUMPRODUCT(--(NOT(ISBLANK('0₦'!Q15:T15))), '0₦'!Q$2:T$2)} | BD15: {=SUMPRODUCT(--(NOT(ISBLANK('0₦'!N15:P15))),'0₦'!N$2:P$2)+'0₦'!AY15} | BE15: {=SUMPRODUCT(--(NOT(ISBLANK('0₦'!AA15:AC15))),'0₦'!AA$2:AC$2) + BF15} | BG15: {=SUMPRODUCT(--(NOT(ISBLANK('0₦'!U15:Z15))), '0₦'!U$2:Z$2)} | BI15: =SUM(BG15:BH15)
B16: Th | C16: =C15+1 | D16: 431 | E16: 2 | F16: 14 | G16: 15 | H16: 1 | I16: 1 | J16: 1 | K16: 2 | L16: 20 | M16: 3 | N16: 20 | O16: 7 | P16: 30 | Q16: 5 | R16: 1 | S16: 4 | T16: 3 | U16: 3 | V16: 7 | W16: 10 | Y16: 10 | Z16: 1 | AA16: 1 | AB16: 14 | AC16: 1 | AD16: 17 | AE16: 1 | AF16: 1400 | AH16: 0 | AI16: 0 | AJ16: 0 | AK16: 15 | AL16: 1 | AM16: 39 | AN16: 14 | AO16: 0 | AP16: 0 | AR16: 65 | AS16: 25 | AT16: 30 | AU16: =N16+O16-14 | AW16: =SUM(AH16:AI16,AJ16/2,AK16:AL16) | AX16: =AM16*0.5+SUM(AN16:AP16) | AY16: =SUM(-AR16+AS16*0.01+AT16*0.5+AU16) | AZ16: ='0分'!AF13 | BA16: =SUM(AY16,AX16,AW16) | BC16: {=SUMPRODUCT(--(NOT(ISBLANK('0₦'!D16:M16))), '0₦'!D$2:M$2) + SUMPRODUCT(--(NOT(ISBLANK('0₦'!Q16:T16))), '0₦'!Q$2:T$2)} | BD16: {=SUMPRODUCT(--(NOT(ISBLANK('0₦'!N16:P16))),'0₦'!N$2:P$2)+'0₦'!AY16} | BE16: {=SUMPRODUCT(--(NOT(ISBLANK('0₦'!AA16:AC16))),'0₦'!AA$2:AC$2) + BF16} | BG16: {=SUMPRODUCT(--(NOT(ISBLANK('0₦'!U16:Z16))), '0₦'!U$2:Z$2)} | BI16: =SUM(BG16:BH16)
B17: F | C17: =C16+1 | D17: 475 | E17: 2 | F17: 10 | G17: 15 | H17: 1 | I17: 1 | J17: 1 | K17: 3 | L17: 15 | M17: 2 | N17: 10 | O17: 8 | P17: 20 | Q17: 2 | R17: 1 | S17: 13 | T17: 4 | U17: 4 | V17: 8 | W17: 10 | Y17: 15 | Z17: 1 | AA17: 1 | AB17: 5 | AC17: 1 | AD17: 16 | AE17: 1 | AF17: 841 | AG17: 1339 | AH17: 1 | AI17: 0 | AJ17: 0 | AK17: =10+48 | AL17: 1 | AM17: 67 | AN17: 0 | AO17: 37 | AP17: 28 | AR17: -1 | AS17: 30 | AT17: =10+25 | AU17: 14 | AW17: =SUM(AH17:AI17,AJ17/2,AK17:AL17) | AX17: =AM17*0.5+SUM(AN17:AP17) | AY17: =SUM(-AR17+AS17*0.01+AT17*0.5+AU17) | AZ17: ='0分'!AF14 | BA17: =SUM(AY17,AX17,AW17) | BC17: {=SUMPRODUCT(--(NOT(ISBLANK('0₦'!D17:M17))), '0₦'!D$2:M$2) + SUMPRODUCT(--(NOT(ISBLANK('0₦'!Q17:T17))), '0₦'!Q$2:T$2)} | BD17: {=SUMPRODUCT(--(NOT(ISBLANK('0₦'!N17:P17))),'0₦'!N$2:P$2)+'0₦'!AY17} | BE17: {=SUMPRODUCT(--(NOT(ISBLANK('0₦'!AA17:AC17))),'0₦'!AA$2:AC$2) + BF17} | BG17: {=SUMPRODUCT(--(NOT(ISBLANK('0₦'!U17:Z17))), '0₦'!U$2:Z$2)} | BI17: =SUM(BG17:BH17)
B18: S | C18: =C17+1 | D18: 449 | E18: 1 | F18: 10 | G18: 25 | H18: 1 | I18: 1 | J18: 1 | K18: 3 | L18: 10 | M18: 2 | N18: 11 | O18: 6 | P18: 30 | Q18: 5 | R18: 1 | S18: 8 | T18: 4 | U18: 5 | V18: 3 | W18: 21 | Y18: 6 | Z18: 1 | AA18: 1 | AB18: 5 | AC18: 1 | AD18: 10 | AE18: 20 | AF18: 904 | AG18: 1937 | AH18: 0 | AI18: =38+15+10+5+10 + 89+5 | AJ18: 200 | AK18: 60 | AL18: 1 | AM18: 92 | AN18: 0 | AO18: 0 | AP18: 30 | AR18: -1 | AS18: 30 | AT18: 0 | AU18: =N18+O18 | AW18: =SUM(AH18:AI18,AJ18/2,AK18:AL18) | AX18: =AM18*0.5+SUM(AN18:AP18) | AY18: =SUM(-AR18+AS18*0.01+AT18*0.5+AU18) | AZ18: ='0分'!AF15 | BA18: =SUM(AY18,AX18,AW18) | BC18: {=SUMPRODUCT(--(NOT(ISBLANK('0₦'!D18:M18))), '0₦'!D$2:M$2) + SUMPRODUCT(--(NOT(ISBLANK('0₦'!Q18:T18))), '0₦'!Q$2:T$2)} | BD18: {=SUMPRODUCT(--(NOT(ISBLANK('0₦'!N18:P18))),'0₦'!N$2:P$2)+'0₦'!AY18} | BE18: {=SUMPRODUCT(--(NOT(ISBLANK('0₦'!AA18:AC18))),'0₦'!AA$2:AC$2) + BF18} | BG18: {=SUMPRODUCT(--(NOT(ISBLANK('0₦'!U18:Z18))), '0₦'!U$2:Z$2)} | BI18: =SUM(BG18:BH18)
A19: =A12+0.1 | B19: S | C19: =C18+1 | D19: 524 | E19: 2 | F19: 3 | G19: 15 | H19: 1 | I19: 1 | J19: 1 | K19: 3 | L19: 15 | M19: 2 | N19: 10 | O19: 5 | P19: 30 | Q19: 4 | R19: 1 | S19: 8 | T19: 2 | U19: 5 | V19: 1 | W19: 5 | Y19: 1 | Z19: 1 | AA19: 1 | AB19: 13 | AC19: 1 | AD19: 15 | AE19: 1 | AF19: 808 | AH19: 0 | AI19: =48+5 + 38 + 5 + 63 + 43 + 10 | AJ19: 200 | AK19: 30 | AL19: 1 | AM19: 65 | AN19: 0 | AO19: 0 | AP19: 0 | AR19: -1 | AS19: 0 | AT19: 0 | AU19: 24 | AW19: =SUM(AH19:AI19,AJ19/2,AK19:AL19) | AX19: =AM19*0.5+SUM(AN19:AP19) | AY19: =SUM(-AR19+AS19*0.01+AT19*0.5+AU19) | AZ19: ='0分'!AF16 | BA19: =SUM(AY19,AX19,AW19) | BC19: {=SUMPRODUCT(--(NOT(ISBLANK('0₦'!D19:M19))), '0₦'!D$2:M$2) + SUMPRODUCT(--(NOT(ISBLANK('0₦'!Q19:T19))), '0₦'!Q$2:T$2)} | BD19: {=SUMPRODUCT(--(NOT(ISBLANK('0₦'!N19:P19))),'0₦'!N$2:P$2)+'0₦'!AY19} | BE19: {=SUMPRODUCT(--(NOT(ISBLANK('0₦'!AA19:AC19))),'0₦'!AA$2:AC$2) + BF19} | BG19: {=SUMPRODUCT(--(NOT(ISBLANK('0₦'!U19:Z19))), '0₦'!U$2:Z$2)} | BI19: =SUM(BG19:BH19)
B20: M | C20: =C19+1 | D20: 566 | E20: 2 | F20: 15 | G20: 30 | H20: 1 | I20: 1 | J20: 1 | K20: 3 | L20: 15 | M20: 2 | N20: 12 | O20: 5 | P20: 30 | Q20: 4 | R20: 1 | S20: 10 | T20: 5 | V20: 2 | W20: 10 | Y20: 5 | Z20: 1 | AA20: 1 | AB20: 9 | AC20: 1 | AD20: 10 | AE20: 1 | AF20: 3000 | AH20: 1 | AI20: =78+8+10 | AJ20: 200 | AK20: 120 | AL20: 1 | AM20: 79 | AN20: 20 | AO20: 0 | AP20: 14 | AR20: -1 | AS20: 90 | AT20: 0 | AU20: =N20 | AW20: =SUM(AH20:AI20,AJ20/2,AK20:AL20) | AX20: =AM20*0.5+SUM(AN20:AP20) | AY20: =SUM(-AR20+AS20*0.01+AT20*0.5+AU20) | AZ20: ='0分'!AF17 | BA20: =SUM(AY20,AX20,AW20) | BC20: {=SUMPRODUCT(--(NOT(ISBLANK('0₦'!D20:M20))), '0₦'!D$2:M$2) + SUMPRODUCT(--(NOT(ISBLANK('0₦'!Q20:T20))), '0₦'!Q$2:T$2)} | BD20: {=SUMPRODUCT(--(NOT(ISBLANK('0₦'!N20:P20))),'0₦'!N$2:P$2)+'0₦'!AY20} | BE20: {=SUMPRODUCT(--(NOT(ISBLANK('0₦'!AA20:AC20))),'0₦'!AA$2:AC$2) + BF20} | BG20: {=SUMPRODUCT(--(NOT(ISBLANK('0₦'!U20:Z20))), '0₦'!U$2:Z$2)} | BI20: =SUM(BG20:BH20)
B21: T | C21: =C20+1 | D21: 555 | E21: 1 | F21: 10 | H21: 1 | I21: 1 | J21: 1 | K21: 4 | L21: 15 | M21: 1 | N21: 11 | O21: 6 | P21: 90 | Q21: 5 | R21: 1 | S21: 4 | T21: 4 | U21: 5 | V21: 3 | W21: 10 | X21: 8 | Y21: 5 | Z21: 1 | AA21: 1 | AB21: 9 | AC21: 1 | AD21: 8 | AE21: 1 | AF21: 955 | AG21: 1014 | AH21: 2 | AI21: =24+31+10 | AJ21: 0 | AK21: =32+27 | AL21: 1 | AM21: 78 | AN21: 42 | AO21: 18 | AP21: 18 | AR21: -1 | AS21: 20 | AT21: 18 | AU21: =N21+O21 + 10 + 21 + 25 | AW21: =SUM(AH21:AI21,AJ21/2,AK21:AL21) | AX21: =AM21*0.5+SUM(AN21:AP21) | AY21: =SUM(-AR21+AS21*0.01+AT21*0.5+AU21) | AZ21: ='0分'!AF18 | BA21: =SUM(AY21,AX21,AW21) | BC21: {=SUMPRODUCT(--(NOT(ISBLANK('0₦'!D21:M21))), '0₦'!D$2:M$2) + SUMPRODUCT(--(NOT(ISBLANK('0₦'!Q21:T21))), '0₦'!Q$2:T$2)} | BD21: {=SUMPRODUCT(--(NOT(ISBLANK('0₦'!N21:P21))),'0₦'!N$2:P$2)+'0₦'!AY21} | BE21: {=SUMPRODUCT(--(NOT(ISBLANK('0₦'!AA21:AC21))),'0₦'!AA$2:AC$2) + BF21} | BG21: {=SUMPRODUCT(--(NOT(ISBLANK('0₦'!U21:Z21))), '0₦'!U$2:Z$2)} | BI21: =SUM(BG21:BH21)
B22: W | C22: =C21+1 | D22: 496 | E22: 0 | F22: 10 | G22: 15 | H22: 1 | I22: 1 | J22: 1 | K22: 4 | L22: 25 | M22: 2 | N22: 11 | P22: 20 | Q22: 4 | R22: 1 | S22: 5 | T22: 4 | U22: 7 | V22: 5 | W22: 10 | Y22: 10 | Z22: 1 | AA22: 5 | AB22: 15 | AC22: 1 | AD22: 20 | AE22: 1 | AF22: 826 | AG22: 2115 | AH22: 1 | AI22: 0 | AJ22: 0 | AK22: =15 | AL22: 1 | AM22: 25 | AN22: 0 | AO22: =15+15 | AP22: 0 | AR22: 1 | AS22: 0 | AT22: 20 | AU22: =N22+O22 + 0 | AW22: =SUM(AH22:AI22,AJ22/2,AK22:AL22) | AX22: =AM22*0.5+SUM(AN22:AP22) | AY22: =SUM(-AR22+AS22*0.01+AT22*0.5+AU22) | AZ22: ='0分'!AF19 | BA22: =SUM(AY22,AX22,AW22) | BC22: {=SUMPRODUCT(--(NOT(ISBLANK('0₦'!D22:M22))), '0₦'!D$2:M$2) + SUMPRODUCT(--(NOT(ISBLANK('0₦'!Q22:T22))), '0₦'!Q$2:T$2)} | BD22: {=SUMPRODUCT(--(NOT(ISBLANK('0₦'!N22:P22))),'0₦'!N$2:P$2)+'0₦'!AY22} | BE22: {=SUMPRODUCT(--(NOT(ISBLANK('0₦'!AA22:AC22))),'0₦'!AA$2:AC$2) + BF22} | BG22: {=SUMPRODUCT(--(NOT(ISBLANK('0₦'!U22:Z22))), '0₦'!U$2:Z$2)} | BI22: =SUM(BG22:BH22)
B23: Th | C23: =C22+1 | D23: 540 | E23: 0 | F23: 10 | G23: 15 | H23: 1 | I23: 1 | J23: 1 | K23: 3 | L23: 15 | M23: 2 | N23: 11 | P23: 5 | Q23: 2 | R23: 1 | S23: 3 | T23: 4 | U23: 6 | V23: 8 | W23: 10 | X23: 0 | Y23: 10 | Z23: 1 | AA23: 1 | AB23: 25 | AC23: 1 | AD23: 7 | AE23: 18 | AF23: 749 | AH23: 0 | AI23: 0 | AJ23: 0 | AK23: =18 + 29 | AL23: 1 | AM23: 63 | AN23: 50 | AO23: =15+31+22 | AP23: 0 | AR23: -1 | AS23: 0 | AT23: 0 | AU23: =N23+O23 + 0 | AW23: =SUM(AH23:AI23,AJ23/2,AK23:AL23) | AX23: =AM23*0.5+SUM(AN23:AP23) | AY23: =SUM(-AR23+AS23*0.01+AT23*0.5+AU23) | AZ23: ='0分'!AF20 | BA23: =SUM(AY23,AX23,AW23) | BC23: {=SUMPRODUCT(--(NOT(ISBLANK('0₦'!D23:M23))), '0₦'!D$2:M$2) + SUMPRODUCT(--(NOT(ISBLANK('0₦'!Q23:T23))), '0₦'!Q$2:T$2)} | BD23: {=SUMPRODUCT(--(NOT(ISBLANK('0₦'!N23:P23))),'0₦'!N$2:P$2)+'0₦'!AY23} | BE23: {=SUMPRODUCT(--(NOT(ISBLANK('0₦'!AA23:AC23))),'0₦'!AA$2:AC$2) + BF23} | BG23: {=SUMPRODUCT(--(NOT(ISBLANK('0₦'!U23:Z23))), '0₦'!U$2:Z$2)} | BI23: =SUM(BG23:BH23)
B24: F | C24: =C23+1 | D24: 471 | E24: 0 | F24: 15 | G24: 15 | H24: 1 | I24: 1 | J24: 1 | K24: 7 | M24: 2 | N24: 11 | P24: 15 | Q24: 2 | R24: 1 | S24: 5 | T24: 4 | U24: 4 | V24: 4 | W24: 10 | Y24: 15 | Z24: 1 | AA24: 1 | AB24: 2 | AC24: 1 | AD24: 10 | AE24: 25 | AF24: 735 | AG24: 1138 | AH24: 1 | AI24: =120+20 | AJ24: 20 | AK24: =25+15 | AL24: 1 | AM24: 51 | AN24: 24 | AO24: 31 | AP24: 0 | AR24: -1 | AS24: 0 | AT24: 85 | AU24: =N24+O24 + 23 | AW24: =SUM(AH24:AI24,AJ24/2,AK24:AL24) | AX24: =AM24*0.5+SUM(AN24:AP24) | AY24: =SUM(-AR24+AS24*0.01+AT24*0.5+AU24) | AZ24: ='0分'!AF21 | BA24: =SUM(AY24,AX24,AW24) | BC24: {=SUMPRODUCT(--(NOT(ISBLANK('0₦'!D24:M24))), '0₦'!D$2:M$2) + SUMPRODUCT(--(NOT(ISBLANK('0₦'!Q24:T24))), '0₦'!Q$2:T$2)} | BD24: {=SUMPRODUCT(--(NOT(ISBLANK('0₦'!N24:P24))),'0₦'!N$2:P$2)+'0₦'!AY24} | BE24: {=SUMPRODUCT(--(NOT(ISBLANK('0₦'!AA24:AC24))),'0₦'!AA$2:AC$2) + BF24} | BG24: {=SUMPRODUCT(--(NOT(ISBLANK('0₦'!U24:Z24))), '0₦'!U$2:Z$2)} | BI24: =SUM(BG24:BH24)
B25: S | C25: =C24+1 | D25: 522 | E25: 0 | F25: 15 | G25: 15 | H25: 1 | I25: 1 | J25: 1 | M25: 3 | N25: 12 | P25: 2 | R25: 1 | AH25: 0 | AM25: 4 | AN25: 0 | AO25: 0 | AP25: 0 | AR25: -1 | AT25: 2 | AU25: =N25+O25 + 0 | AW25: =SUM(AH25:AI25,AJ25/2,AK25:AL25) | AX25: =AM25*0.5+SUM(AN25:AP25) | AY25: =SUM(-AR25+AS25*0.01+AT25*0.5+AU25) | AZ25: ='0分'!AF22 | BA25: =SUM(AY25,AX25,AW25) | BC25: {=SUMPRODUCT(--(NOT(ISBLANK('0₦'!D25:M25))), '0₦'!D$2:M$2) + SUMPRODUCT(--(NOT(ISBLANK('0₦'!Q25:T25))), '0₦'!Q$2:T$2)} | BD25: {=SUMPRODUCT(--(NOT(ISBLANK('0₦'!N25:P25))),'0₦'!N$2:P$2)+'0₦'!AY25} | BE25: {=SUMPRODUCT(--(NOT(ISBLANK('0₦'!AA25:AC25))),'0₦'!AA$2:AC$2) + BF25} | BG25: {=SUMPRODUCT(--(NOT(ISBLANK('0₦'!U25:Z25))), '0₦'!U$2:Z$2)} | BI25: =SUM(BG25:BH25)
A26: =A19+0.1 | B26: S | C26: =C25+1 | AR26: 40 | AU26: =N26+O26 + 0 | AW26: =SUM(AH26:AI26,AJ26/2,AK26:AL26) | AX26: =AM26*0.5+SUM(AN26:AP26) | AY26: =SUM(-AR26+AS26*0.01+AT26*0.5+AU26) | AZ26: ='0分'!AF23 | BA26: =SUM(AY26,AX26,AW26) | BC26: {=SUMPRODUCT(--(NOT(ISBLANK('0₦'!D26:M26))), '0₦'!D$2:M$2) + SUMPRODUCT(--(NOT(ISBLANK('0₦'!Q26:T26))), '0₦'!Q$2:T$2)} | BD26: {=SUMPRODUCT(--(NOT(ISBLANK('0₦'!N26:P26))),'0₦'!N$2:P$2)+'0₦'!AY26} | BE26: {=SUMPRODUCT(--(NOT(ISBLANK('0₦'!AA26:AC26))),'0₦'!AA$2:AC$2) + BF26} | BG26: {=SUMPRODUCT(--(NOT(ISBLANK('0₦'!U26:Z26))), '0₦'!U$2:Z$2)} | BI26: =SUM(BG26:BH26)
B27: M | C27: =C26+1 | AR27: 40 | AU27: =N27+O27 + 0 | AW27: =SUM(AH27:AI27,AJ27/2,AK27:AL27) | AX27: =AM27*0.5+SUM(AN27:AP27) | AY27: =SUM(-AR27+AS27*0.01+AT27*0.5+AU27) | AZ27: ='0分'!AF24 | BA27: =SUM(AY27,AX27,AW27) | BC27: {=SUMPRODUCT(--(NOT(ISBLANK('0₦'!D27:M27))), '0₦'!D$2:M$2) + SUMPRODUCT(--(NOT(ISBLANK('0₦'!Q27:T27))), '0₦'!Q$2:T$2)} | BD27: {=SUMPRODUCT(--(NOT(ISBLANK('0₦'!N27:P27))),'0₦'!N$2:P$2)+'0₦'!AY27} | BE27: {=SUMPRODUCT(--(NOT(ISBLANK('0₦'!AA27:AC27))),'0₦'!AA$2:AC$2) + BF27} | BG27: {=SUMPRODUCT(--(NOT(ISBLANK('0₦'!U27:Z27))), '0₦'!U$2:Z$2)} | BI27: =SUM(BG27:BH27)
B28: T | C28: =C27+1 | AR28: 40 | AU28: =N28+O28 + 0 | AW28: =SUM(AH28:AI28,AJ28/2,AK28:AL28) | AX28: =AM28*0.5+SUM(AN28:AP28) | AY28: =SUM(-AR28+AS28*0.01+AT28*0.5+AU28) | AZ28: ='0分'!AF25 | BA28: =SUM(AY28,AX28,AW28) | BC28: {=SUMPRODUCT(--(NOT(ISBLANK('0₦'!D28:M28))), '0₦'!D$2:M$2) + SUMPRODUCT(--(NOT(ISBLANK('0₦'!Q28:T28))), '0₦'!Q$2:T$2)} | BD28: {=SUMPRODUCT(--(NOT(ISBLANK('0₦'!N28:P28))),'0₦'!N$2:P$2)+'0₦'!AY28} | BE28: {=SUMPRODUCT(--(NOT(ISBLANK('0₦'!AA28:AC28))),'0₦'!AA$2:AC$2) + BF28} | BG28: {=SUMPRODUCT(--(NOT(ISBLANK('0₦'!U28:Z28))), '0₦'!U$2:Z$2)} | BI28: =SUM(BG28:BH28)
B29: W | C29: =C28+1 | AR29: 40 | AU29: =N29+O29 + 0 | AW29: =SUM(AH29:AI29,AJ29/2,AK29:AL29) | AX29: =AM29*0.5+SUM(AN29:AP29) | AY29: =SUM(-AR29+AS29*0.01+AT29*0.5+AU29) | AZ29: ='0分'!AF26 | BA29: =SUM(AY29,AX29,AW29) | BC29: {=SUMPRODUCT(--(NOT(ISBLANK('0₦'!D29:M29))), '0₦'!D$2:M$2) + SUMPRODUCT(--(NOT(ISBLANK('0₦'!Q29:T29))), '0₦'!Q$2:T$2)} | BD29: {=SUMPRODUCT(--(NOT(ISBLANK('0₦'!N29:P29))),'0₦'!N$2:P$2)+'0₦'!AY29} | BE29: {=SUMPRODUCT(--(NOT(ISBLANK('0₦'!AA29:AC29))),'0₦'!AA$2:AC$2) + BF29} | BG29: {=SUMPRODUCT(--(NOT(ISBLANK('0₦'!U29:Z29))), '0₦'!U$2:Z$2)} | BI29: =SUM(BG29:BH29)
B30: Th | C30: =C29+1 | AR30: 40 | AU30: =N30+O30 + 0 | AW30: =SUM(AH30:AI30,AJ30/2,AK30:AL30) | AX30: =AM30*0.5+SUM(AN30:AP30) | AY30: =SUM(-AR30+AS30*0.01+AT30*0.5+AU30) | AZ30: ='0分'!AF27 | BA30: =SUM(AY30,AX30,AW30) | BC30: {=SUMPRODUCT(--(NOT(ISBLANK('0₦'!D30:M30))), '0₦'!D$2:M$2) + SUMPRODUCT(--(NOT(ISBLANK('0₦'!Q30:T30))), '0₦'!Q$2:T$2)} | BD30: {=SUMPRODUCT(--(NOT(ISBLANK('0₦'!N30:P30))),'0₦'!N$2:P$2)+'0₦'!AY30} | BE30: {=SUMPRODUCT(--(NOT(ISBLANK('0₦'!AA30:AC30))),'0₦'!AA$2:AC$2) + BF30} | BG30: {=SUMPRODUCT(--(NOT(ISBLANK('0₦'!U30:Z30))), '0₦'!U$2:Z$2)} | BI30: =SUM(BG30:BH30)
B31: F | C31: =C30+1 | AR31: 40 | AU31: =N31+O31 + 0 | AW31: =SUM(AH31:AI31,AJ31/2,AK31:AL31) | AX31: =AM31*0.5+SUM(AN31:AP31) | AY31: =SUM(-AR31+AS31*0.01+AT31*0.5+AU31) | AZ31: ='0分'!AF28 | BA31: =SUM(AY31,AX31,AW31) | BC31: {=SUMPRODUCT(--(NOT(ISBLANK('0₦'!D31:M31))), '0₦'!D$2:M$2) + SUMPRODUCT(--(NOT(ISBLANK('0₦'!Q31:T31))), '0₦'!Q$2:T$2)} | BD31: {=SUMPRODUCT(--(NOT(ISBLANK('0₦'!N31:P31))),'0₦'!N$2:P$2)+'0₦'!AY31} | BE31: {=SUMPRODUCT(--(NOT(ISBLANK('0₦'!AA31:AC31))),'0₦'!AA$2:AC$2) + BF31} | BG31: {=SUMPRODUCT(--(NOT(ISBLANK('0₦'!U31:Z31))), '0₦'!U$2:Z$2)} | BI31: =SUM(BG31:BH31)
B32: S | C32: =C31+1 | AR32: 40 | AU32: =N32+O32 + 0 | AW32: =SUM(AH32:AI32,AJ32/2,AK32:AL32) | AX32: =AM32*0.5+SUM(AN32:AP32) | AY32: =SUM(-AR32+AS32*0.01+AT32*0.5+AU32) | AZ32: ='0分'!AF29 | BA32: =SUM(AY32,AX32,AW32) | BC32: {=SUMPRODUCT(--(NOT(ISBLANK('0₦'!D32:M32))), '0₦'!D$2:M$2) + SUMPRODUCT(--(NOT(ISBLANK('0₦'!Q32:T32))), '0₦'!Q$2:T$2)} | BD32: {=SUMPRODUCT(--(NOT(ISBLANK('0₦'!N32:P32))),'0₦'!N$2:P$2)+'0₦'!AY32} | BE32: {=SUMPRODUCT(--(NOT(ISBLANK('0₦'!AA32:AC32))),'0₦'!AA$2:AC$2) + BF32} | BG32: {=SUMPRODUCT(--(NOT(ISBLANK('0₦'!U32:Z32))), '0₦'!U$2:Z$2)} | BI32: =SUM(BG32:BH32)
A33: =A5+1 | B33: S | C33: =C32+1 | AR33: 40 | AU33: =N33+O33 + 0 | AW33: =SUM(AH33:AI33,AJ33/2,AK33:AL33) | AX33: =AM33*0.5+SUM(AN33:AP33) | AY33: =SUM(-AR33+AS33*0.01+AT33*0.5+AU33) | AZ33: ='0分'!AF30 | BA33: =SUM(AY33,AX33,AW33) | BC33: {=SUMPRODUCT(--(NOT(ISBLANK('0₦'!D33:M33))), '0₦'!D$2:M$2) + SUMPRODUCT(--(NOT(ISBLANK('0₦'!Q33:T33))), '0₦'!Q$2:T$2)} | BD33: {=SUMPRODUCT(--(NOT(ISBLANK('0₦'!N33:P33))),'0₦'!N$2:P$2)+'0₦'!AY33} | BE33: {=SUMPRODUCT(--(NOT(ISBLANK('0₦'!AA33:AC33))),'0₦'!AA$2:AC$2) + BF33} | BG33: {=SUMPRODUCT(--(NOT(ISBLANK('0₦'!U33:Z33))), '0₦'!U$2:Z$2)} | BI33: =SUM(BG33:BH33)
B34: M | C34: =C33+1 | AR34: 40 | AU34: =N34+O34 + 0 | AW34: =SUM(AH34:AI34,AJ34/2,AK34:AL34) | AX34: =AM34*0.5+SUM(AN34:AP34) | AY34: =SUM(-AR34+AS34*0.01+AT34*0.5+AU34) | AZ34: ='0分'!AF31 | BA34: =SUM(AY34,AX34,AW34) | BC34: {=SUMPRODUCT(--(NOT(ISBLANK('0₦'!D34:M34))), '0₦'!D$2:M$2) + SUMPRODUCT(--(NOT(ISBLANK('0₦'!Q34:T34))), '0₦'!Q$2:T$2)} | BD34: {=SUMPRODUCT(--(NOT(ISBLANK('0₦'!N34:P34))),'0₦'!N$2:P$2)+'0₦'!AY34} | BE34: {=SUMPRODUCT(--(NOT(ISBLANK('0₦'!AA34:AC34))),'0₦'!AA$2:AC$2) + BF34} | BG34: {=SUMPRODUCT(--(NOT(ISBLANK('0₦'!U34:Z34))), '0₦'!U$2:Z$2)} | BI34: =SUM(BG34:BH34)
B35: T | C35: =C34+1 | AR35: 40 | AU35: =N35+O35 + 0 | AW35: =SUM(AH35:AI35,AJ35/2,AK35:AL35) | AX35: =AM35*0.5+SUM(AN35:AP35) | AY35: =SUM(-AR35+AS35*0.01+AT35*0.5+AU35) | AZ35: ='0分'!AF32 | BA35: =SUM(AY35,AX35,AW35) | BC35: {=SUMPRODUCT(--(NOT(ISBLANK('0₦'!D35:M35))), '0₦'!D$2:M$2) + SUMPRODUCT(--(NOT(ISBLANK('0₦'!Q35:T35))), '0₦'!Q$2:T$2)} | BD35: {=SUMPRODUCT(--(NOT(ISBLANK('0₦'!N35:P35))),'0₦'!N$2:P$2)+'0₦'!AY35} | BE35: {=SUMPRODUCT(--(NOT(ISBLANK('0₦'!AA35:AC35))),'0₦'!AA$2:AC$2) + BF35} | BG35: {=SUMPRODUCT(--(NOT(ISBLANK('0₦'!U35:Z35))), '0₦'!U$2:Z$2)} | BI35: =SUM(BG35:BH35)
B36: W | C36: =C35+1 | AR36: 40 | AU36: =N36+O36 + 0 | AW36: =SUM(AH36:AI36,AJ36/2,AK36:AL36) | AX36: =AM36*0.5+SUM(AN36:AP36) | AY36: =SUM(-AR36+AS36*0.01+AT36*0.5+AU36) | AZ36: ='0分'!AF33 | BA36: =SUM(AY36,AX36,AW36) | BC36: {=SUMPRODUCT(--(NOT(ISBLANK('0₦'!D36:M36))), '0₦'!D$2:M$2) + SUMPRODUCT(--(NOT(ISBLANK('0₦'!Q36:T36))), '0₦'!Q$2:T$2)} | BD36: {=SUMPRODUCT(--(NOT(ISBLANK('0₦'!N36:P36))),'0₦'!N$2:P$2)+'0₦'!AY36} | BE36: {=SUMPRODUCT(--(NOT(ISBLANK('0₦'!AA36:AC36))),'0₦'!AA$2:AC$2) + BF36} | BG36: {=SUMPRODUCT(--(NOT(ISBLANK('0₦'!U36:Z36))), '0₦'!U$2:Z$2)} | BI36: =SUM(BG36:BH36)
B37: Th | C37: =C36+1 | AR37: 40 | AU37: =N37+O37 + 0 | AW37: =SUM(AH37:AI37,AJ37/2,AK37:AL37) | AX37: =AM37*0.5+SUM(AN37:AP37) | AY37: =SUM(-AR37+AS37*0.01+AT37*0.5+AU37) | AZ37: ='0分'!AF34 | BA37: =SUM(AY37,AX37,AW37) | BC37: {=SUMPRODUCT(--(NOT(ISBLANK('0₦'!D37:M37))), '0₦'!D$2:M$2) + SUMPRODUCT(--(NOT(ISBLANK('0₦'!Q37:T37))), '0₦'!Q$2:T$2)} | BD37: {=SUMPRODUCT(--(NOT(ISBLANK('0₦'!N37:P37))),'0₦'!N$2:P$2)+'0₦'!AY37} | BE37: {=SUMPRODUCT(--(NOT(ISBLANK('0₦'!AA37:AC37))),'0₦'!AA$2:AC$2) + BF37} | BG37: {=SUMPRODUCT(--(NOT(ISBLANK('0₦'!U37:Z37))), '0₦'!U$2:Z$2)} | BI37: =SUM(BG37:BH37)
B38: F | C38: =C37+1 | AR38: 40 | AU38: =N38+O38 + 0 | AW38: =SUM(AH38:AI38,AJ38/2,AK38:AL38) | AX38: =AM38*0.5+SUM(AN38:AP38) | AY38: =SUM(-AR38+AS38*0.01+AT38*0.5+AU38) | AZ38: ='0分'!AF35 | BA38: =SUM(AY38,AX38,AW38) | BC38: {=SUMPRODUCT(--(NOT(ISBLANK('0₦'!D38:M38))), '0₦'!D$2:M$2) + SUMPRODUCT(--(NOT(ISBLANK('0₦'!Q38:T38))), '0₦'!Q$2:T$2)} | BD38: {=SUMPRODUCT(--(NOT(ISBLANK('0₦'!N38:P38))),'0₦'!N$2:P$2)+'0₦'!AY38} | BE38: {=SUMPRODUCT(--(NOT(ISBLANK('0₦'!AA38:AC38))),'0₦'!AA$2:AC$2) + BF38} | BG38: {=SUMPRODUCT(--(NOT(ISBLANK('0₦'!U38:Z38))), '0₦'!U$2:Z$2)} | BI38: =SUM(BG38:BH38)
B39: S | C39: =C38+1 | AR39: 40 | AU39: =N39+O39 + 0 | AW39: =SUM(AH39:AI39,AJ39/2,AK39:AL39) | AX39: =AM39*0.5+SUM(AN39:AP39) | AY39: =SUM(-AR39+AS39*0.01+AT39*0.5+AU39) | AZ39: ='0分'!AF36 | BA39: =SUM(AY39,AX39,AW39) | BC39: {=SUMPRODUCT(--(NOT(ISBLANK('0₦'!D39:M39))), '0₦'!D$2:M$2) + SUMPRODUCT(--(NOT(ISBLANK('0₦'!Q39:T39))), '0₦'!Q$2:T$2)} | BD39: {=SUMPRODUCT(--(NOT(ISBLANK('0₦'!N39:P39))),'0₦'!N$2:P$2)+'0₦'!AY39} | BE39: {=SUMPRODUCT(--(NOT(ISBLANK('0₦'!AA39:AC39))),'0₦'!AA$2:AC$2) + BF39} | BG39: {=SUMPRODUCT(--(NOT(ISBLANK('0₦'!U39:Z39))), '0₦'!U$2:Z$2)} | BI39: =SUM(BG39:BH39)
A40: =A33+0.1 | B40: S | C40: =C39+1 | AR40: 40 | AU40: =N40+O40 + 0 | AW40: =SUM(AH40:AI40,AJ40/2,AK40:AL40) | AX40: =AM40*0.5+SUM(AN40:AP40) | AY40: =SUM(-AR40+AS40*0.01+AT40*0.5+AU40) | AZ40: ='0分'!AF37 | BA40: =SUM(AY40,AX40,AW40) | BC40: {=SUMPRODUCT(--(NOT(ISBLANK('0₦'!D40:M40))), '0₦'!D$2:M$2) + SUMPRODUCT(--(NOT(ISBLANK('0₦'!Q40:T40))), '0₦'!Q$2:T$2)} | BD40: {=SUMPRODUCT(--(NOT(ISBLANK('0₦'!N40:P40))),'0₦'!N$2:P$2)+'0₦'!AY40} | BE40: {=SUMPRODUCT(--(NOT(ISBLANK('0₦'!AA40:AC40))),'0₦'!AA$2:AC$2) + BF40} | BG40: {=SUMPRODUCT(--(NOT(ISBLANK('0₦'!U40:Z40))), '0₦'!U$2:Z$2)} | BI40: =SUM(BG40:BH40)
...

Sheet 0s
A1: 周 | B1: 5^0 | C1: dow | D1: What is my motivation for today? | E1: Title of the Day | F1: Who did I notice | G1: What am I thankful for? | H1: What was the biggest win today? (غسق} | I1: What was the biggest missed opportunity today? | J1: c084 | K1: 霓虹 | L1: 帮助 | M1: 身体 | N1: Body Notes | O1: ₹ | P1: ⌈ | Q1: ⌊ | R1: x̄ | S1: What am I proud of with regards to others? | T1: What do I regret with regards to others? | U1: Curriculum | V1: ⌈ | W1: ⌊ | X1: 1 hcme | Z1: Time | AA1: Event Review | AB1: Notes for Improvement / Upcoming | AD1: Name | AE1: Dates | AF1: Category | AG1: 分 | AH1: How I got out of it | AI1: Notes
A2: 1.1 | B2: 46023 | C2: Th | D2: n/a | E2: Slipping into Video Games | G2: It's nice to not feel guilty about gaming | H2: Able to track the day | I2: I think better to play video games after LAN | K2: 1 | L2: 1 | M2: 8 | O2: 514 | P2: 7.5 | Q2: 6 | R2: 6.5 | S2: Math in the morning | T2: Gaming is not the best use of time | V2: 7.5 | W2: 6.5 | X2: • Café Juanita, combined with the ability to have a little bit of 享受, was definitely a highlight of the week. • Getting to do neon in the morning is such a blessing. I should really keep doing it, and keep going to bed early to enable it. • I think I should continue to bow out of meetings or conferences if tehy are a waste of time or I'm not caught up on neon. • Interesting but not surprising that the stress pinches when I try and pick up for the slack left behind (i.e. Saturday rather than Thursday) | Z2: 641 | AA2: • LAN Party: B- [中量] • Call with Forest A | AB2: • The rule should be 1:1 time in event vs. prep for event, key being that I'm not the one doing the prep. • I can plan these things super far in advance. • Calling people is a great thing and I should keep doing it, even if at random.
B3: =B2+1 | C3: F | D3: n/a | E3: Reviving the LAN Party | G3: I can still find enjoyment in the adrenaline cycle | H3: Put together and executed the LAN party | I3: Playing AOE wasn't as coordinated as I wanted it to be | K3: 0 | L3: 1 | M3: 6 | N3: oof the shoes hurt | O3: 1199 | P3: 7.8 | Q3: 6.5 | R3: 7 | S3: Gave Forest a call | T3: Took a little debt from future days | V3: 7.5 | W3: 6.5
B4: =B3+1 | C4: S | D4: Family time is still my time | E4: Pay off family debt | G4: I found time in the evening | H4: Got some of the g245 done | I4: Didn't do neon in the morning | K4: 1 | L4: 1 | M4: 6 | O4: 1562 | P4: 7.5 | Q4: 5.5 | R4: 7 | S4: Good time with fam | T4: nervous about going back to work | V4: 7.5 | W4: 6.5
B5: =B4+1 | C5: S | D5: Be confident in my next step | E5: Pay off 0l debt | G5: Energy to get something meaningful done | H5: Getting through 0l | I5: Didn’t get to work | K5: 1 | L5: 1 | M5: 8 | O5: ='0分'!D2 | P5: 7.8 | Q5: 6 | R5: 7.1 | S5: They did lego together | T5: I did not like the walk | V5: 7.5 | W5: 5.5
